<robot name="morpheus">

  <material name="Black">
    <color rgba="0.0 0.0 0.0 1.0"/>
  </material>
  <material name="Blue">
    <color rgba="0.0 0.0 0.8 1.0"/>
  </material>
  <material name="Green">
    <color rgba="0.0 0.8 0.0 1.0"/>
  </material>
  <material name="Grey">
    <color rgba="0.5 0.5 0.5 1.0"/>
  </material>
  <material name="Light_Grey">
    <color rgba="0.8 0.8 0.8 1.0"/>
  </material>
  <material name="Ivory">
    <color rgba="1.0 1.0 0.94 1.0"/>
  </material>
  <material name="Orange">
    <color rgba="1.0 0.423529411765 0.0392156862745 1.0"/>
  </material>
  <material name="Brown">
    <color rgba="0.870588235294 0.811764705882 0.764705882353 1.0"/>
  </material>
  <material name="Red">
    <color rgba="0.8 0.0 0.0 1.0"/>
  </material>
  <material name="White">
    <color rgba="1.0 1.0 1.0 1.0"/>
  </material>

  <link name="base_link">
    <inertial>
      <origin rpy="0 0 0" xyz="-0.0036 0.0 0.0014" />
      <mass value="100.1294" />
      <inertia ixx="1.225" ixy="0.0099" ixz="0.0062" iyy="1.2853" iyz="-0.0034" izz="0.987" />
    </inertial>
    <visual>
      <origin rpy="0 0 0" xyz="0 0 0" />
      <geometry>
        <mesh filename="/home/bill/garage/kfp_v2/morpheus/models/fetch_description/robots/meshes/base_link.dae" />
      </geometry>
      <material name="one">
        <color rgba="0.356 0.361 0.376 1" />
      </material>
    </visual>
    <collision>
      <origin rpy="0 0 0" xyz="0 0 0" />
      <geometry>
        <mesh filename="/home/bill/garage/kfp_v2/morpheus/models/fetch_description/robots/meshes/base_link_collision.STL" />
      </geometry>
    </collision>
  </link>
  <link name="r_wheel_link">
    <inertial>
      <origin rpy="0 0 0" xyz="0 0 0" />
      <mass value="4.3542" />
      <inertia ixx="0.0045" ixy="0" ixz="0" iyy="0.005" iyz="0" izz="0.0045" />
    </inertial>
    <visual>
      <origin rpy="0 0 0" xyz="0 0 0" />
      <geometry>
        <mesh filename="/home/bill/garage/kfp_v2/morpheus/models/fetch_description/robots/meshes/r_wheel_link.STL" />
      </geometry>
      <material name="two">
        <color rgba="0.086 0.506 0.767 1" />
      </material>
    </visual>
    <collision>
      <origin rpy="0 0 0" xyz="0 0 0" />
      <geometry>
        <mesh filename="/home/bill/garage/kfp_v2/morpheus/models/fetch_description/robots/meshes/r_wheel_link_collision.STL" />
      </geometry>
    </collision>
  </link>
  <joint name="r_wheel_joint" type="continuous">
    <origin rpy="-6.123E-17 0 0" xyz="0.0012914 -0.18738 0.055325" />
    <parent link="base_link" />
    <child link="r_wheel_link" />
    <axis xyz="0 1 0" />
  <limit effort="8.85" velocity="34.8" /></joint>
  <link name="l_wheel_link">
    <inertial>
      <origin rpy="0 0 0" xyz="0 0 0" />
      <mass value="4.3542" />
      <inertia ixx="0.0045" ixy="0" ixz="0" iyy="0.005" iyz="0" izz="0.0045" />
    </inertial>
    <visual>
      <origin rpy="0 0 0" xyz="0 0 0" />
      <geometry>
        <mesh filename="/home/bill/garage/kfp_v2/morpheus/models/fetch_description/robots/meshes/l_wheel_link.STL" />
      </geometry>
      <material name="three">
        <color rgba="0.086 0.506 0.767 1" />
      </material>
    </visual>
    <collision>
      <origin rpy="0 0 0" xyz="0 0 0" />
      <geometry>
        <mesh filename="/home/bill/garage/kfp_v2/morpheus/models/fetch_description/robots/meshes/l_wheel_link_collision.STL" />
      </geometry>
    </collision>
  </link>
  <joint name="l_wheel_joint" type="continuous">
    <origin rpy="-6.123E-17 0 0" xyz="0.0012914 0.18738 0.055325" />
    <parent link="base_link" />
    <child link="l_wheel_link" />
    <axis xyz="0 1 0" />
  <limit effort="8.85" velocity="34.8" />
</joint>
  <link name="estop_link">
    <inertial>
      <origin rpy="0 0 0" xyz="0.002434512737072 -0.00330608315239905 0.00665139196650039" />
      <mass value="0.00196130439134723" />
      <inertia ixx="3.02810026604417E-07" ixy="-1.5862023118056E-08" ixz="3.16561396557437E-08" iyy="2.93322917127605E-07" iyz="-4.28833522751273E-08" izz="2.28513272627183E-07" />
    </inertial>
    <visual>
      <origin rpy="0 0 0" xyz="0 0 0" />
      <geometry>
        <mesh filename="/home/bill/garage/kfp_v2/morpheus/models/fetch_description/robots/meshes/estop_link.STL" />
      </geometry>
      <material name="four">
        <color rgba="0.8 0 0 1" />
      </material>
    </visual>
    <collision>
      <origin rpy="0 0 0" xyz="0 0 0" />
      <geometry>
        <mesh filename="/home/bill/garage/kfp_v2/morpheus/models/fetch_description/robots/meshes/estop_link.STL" />
      </geometry>
    </collision>
  </link>
  <joint name="estop_joint" type="fixed">
    <origin rpy="1.5708 0 0" xyz="-0.12465 0.23892 0.31127" />
    <parent link="base_link" />
    <child link="estop_link" />
    <axis xyz="0 0 0" />
  </joint>
  <link name="laser_link">
    <inertial>
      <origin rpy="0 0 0" xyz="-0.0306228970175641 0.0007091682908278 0.0551974119471302" />
      <mass value="0.00833634573995571" />
      <inertia ixx="1.01866461240801E-06" ixy="-5.88447626567756E-08" ixz="7.83857244757914E-08" iyy="5.10039589974707E-07" iyz="-7.12664289617235E-09" izz="1.28270671527309E-06" />
    </inertial>
    <visual>
      <origin rpy="0 0 0" xyz="0 0 0" />
      <geometry>
        <mesh filename="/home/bill/garage/kfp_v2/morpheus/models/fetch_description/robots/meshes/laser_link.STL" />
      </geometry>
      <material name="five">
        <color rgba="0.792156862745098 0.819607843137255 0.933333333333333 1" />
      </material>
    </visual>
    <collision>
      <origin rpy="0 0 0" xyz="0 0 0" />
      <geometry>
        <mesh filename="/home/bill/garage/kfp_v2/morpheus/models/fetch_description/robots/meshes/laser_link.STL" />
      </geometry>
    </collision>
  </link>
  <joint name="laser_joint" type="fixed">
    <origin rpy="3.14159265359 0 0" xyz="0.235 0 0.2878" />
    <parent link="base_link" />
    <child link="laser_link" />
    <axis xyz="0 0 0" />
  </joint>
  <link name="base_camera_link" />
  <joint name="base_camera_joint" type="fixed">
    <origin rpy="0 -0.17453292519943 0" xyz="0.2645 0 0.198" />
    <parent link="base_link" />
    <child link="base_camera_link" />
  </joint>
  <link name="base_camera_optical_frame" />
  <joint name="base_camera_optical_joint" type="fixed">
    <origin rpy="1.5707963267966 0 1.5707963267966" xyz="0 0 0" />
    <parent link="base_camera_link" />
    <child link="base_camera_optical_frame" />
  </joint>
  <link name="pedestal">
    <inertial>
      <origin rpy="0 0 0" xyz="-0.0036 0.0 0.0014" />
      <mass value="7.1294" />
      <inertia ixx="1.225" ixy="0.0099" ixz="0.0062" iyy="1.2853" iyz="-0.0034" izz="0.987" />
    </inertial>
    <visual>
      <origin rpy="0 0 0" xyz="0 0 0" />
      <geometry>
        <box size="0.25 0.25 0.4" />
      </geometry>
      <material name="five">
        <color rgba="0.5 0.5 0.5 1" />
      </material>
    </visual>
    <collision>
      <origin rpy="0 0 0" xyz="0 0 0" />
      <geometry>
        <box size="0.25 0.25 0.4" />
      </geometry>
    </collision>
  </link>
  <joint name="base_to_pedestal" type="fixed">
    <origin rpy="0 0 0" xyz="0 0 0.4" />
    <parent link="base_link"/>
    <child link="pedestal"/>
  </joint>
  <link name="lift">
    <inertial>
      <origin rpy="0 0 0" xyz="-0.0036 0.0 0.0014" />
      <mass value="7.1294" />
      <inertia ixx="1.225" ixy="0.0099" ixz="0.0062" iyy="1.2853" iyz="-0.0034" izz="0.987" />
    </inertial>
    <visual>
      <origin rpy="0 0 0" xyz="0 0 0" />
      <geometry>
        <box size="0.2 0.2 0.3" />
      </geometry>
      <material name="six">
        <color rgba="0.8 0.8 0.8 1" />
      </material>
    </visual>
    <collision>
      <origin rpy="0 0 0" xyz="0 0 0" />
      <geometry>
        <box size="0.2 0.2 0.3" />
      </geometry>
    </collision>
    </link>
  <joint name="pedestal_to_lift" type="fixed">
    <parent link="pedestal"/>
    <child link="lift"/>
    <origin rpy="0 0 0" xyz="0 0 0"/>
    <axis xyz="0 0 1"/>
    <!-- <limit lower="0.0" upper="0.3" effort="30000" velocity="1000"/> -->
  </joint>



  <!--NOW ADDING YUMI-->
  


  <!-- YUMI TO LIFT  -->
  <joint name="lift_to_yumibody" type="fixed">
    <origin rpy="0 0 0" xyz="0.15 0 0.2" />
    <parent link="lift"/>
    <child link="yumi_body"/>
  </joint>

  <link name="yumi_body">
    <inertial>
      <origin rpy="0 0 0" xyz="0 0 0"/>
      <mass value="0.2"/>
      <inertia ixx="0.5" ixy="0" ixz="0" iyy="0.6" iyz="0" izz="0.3"/>
    </inertial>
    <visual>
      <origin rpy="0 0 0" xyz="0 0 0"/>
      <geometry>
        <mesh filename="/home/bill/garage/kfp_v2/morpheus/models/yumi_description/meshes/yumi/body.stl"/>
      </geometry>
      <material name="Light_Grey"/>
    </visual>
    <collision>
      <origin rpy="0 0 0" xyz="0 0 0"/>
      <geometry>
        <mesh filename="/home/bill/garage/kfp_v2/morpheus/models/yumi_description/meshes/yumi/coarse/body.stl"/>
      </geometry>
      <material name="Light_Grey"/>
    </collision>
  </link>
  <!--///////////////////////////////////// RIGHT ARM ////////////////////////////////  -->
  <!-- joint between body and link_1_r -->
  <joint name="yumi_joint_1_r" type="revolute">
    <parent link="yumi_body"/>
    <child link="yumi_link_1_r"/>
    <origin rpy="-0.9795   -0.5682   -2.3155" xyz="0.05355 -0.0725 0.41492"/>
    <axis xyz="0 0 1"/>
    <limit effort="300" lower="-2.8" upper="2.8" velocity="3.14159265359"/>
    <!--   <safety_controller soft_lower_limit="${-168 * M_PI / 180}"
           soft_upper_limit="${168 * M_PI / 180}"
           k_position="${safety_controller_k_pos}"
           k_velocity="${safety_controller_k_vel}"/> -->
    <dynamics damping="0.5"/>
  </joint>
  <link name="yumi_link_1_r">
    <inertial>
      <origin rpy="0 0 0" xyz="0 -0.03 0.12"/>
      <mass value="0.2"/>
      <inertia ixx="0.1" ixy="0" ixz="0" iyy="0.1" iyz="0" izz="0.1"/>
    </inertial>
    <visual>
      <origin rpy="0 0 0" xyz="0 0 0"/>
      <geometry>
        <mesh filename="/home/bill/garage/kfp_v2/morpheus/models/yumi_description/meshes/yumi/link_1.stl"/>
      </geometry>
      <material name="Grey"/>
    </visual>
    <collision>
      <origin rpy="0 0 0" xyz="0 0 0"/>
      <geometry>
        <mesh filename="/home/bill/garage/kfp_v2/morpheus/models/yumi_description/meshes/yumi/coarse/link_1.stl"/>
      </geometry>
      <material name="Grey"/>
    </collision>
  </link>
  <!-- joint between link_1_r and link_2_r -->
  <joint name="yumi_joint_2_r" type="revolute">
    <parent link="yumi_link_1_r"/>
    <child link="yumi_link_2_r"/>
    <origin rpy="1.57079632679 0.0 0.0" xyz="0.03 0.0 0.1"/>
    <axis xyz="0 0 1"/>
    <limit effort="300" lower="-2.4" upper="0.74" velocity="3.14159265359"/>
    <!--   <safety_controller soft_lower_limit="${-168 * M_PI / 180}"
           soft_upper_limit="${168 * M_PI / 180}"
           k_position="${safety_controller_k_pos}"
           k_velocity="${safety_controller_k_vel}"/> -->
    <dynamics damping="0.5"/>
  </joint>
  <link name="yumi_link_2_r">
    <inertial>
      <origin rpy="0 0 0" xyz="0 0 0"/>
      <mass value="0.2"/>
      <inertia ixx="0.1" ixy="0" ixz="0" iyy="0.1" iyz="0" izz="0.1"/>
    </inertial>
    <visual>
      <origin rpy="0 0 0" xyz="0 0 0"/>
      <geometry>
        <mesh filename="/home/bill/garage/kfp_v2/morpheus/models/yumi_description/meshes/yumi/link_2.stl"/>
      </geometry>
      <material name="Grey"/>
    </visual>
    <collision>
      <origin rpy="0 0 0" xyz="0 0 0"/>
      <geometry>
        <mesh filename="/home/bill/garage/kfp_v2/morpheus/models/yumi_description/meshes/yumi/coarse/link_2.stl"/>
      </geometry>
      <material name="Grey"/>
    </collision>
  </link>
  <!-- joint between link_2_r and link_3_r -->
  <joint name="yumi_joint_7_r" type="revolute">
    <parent link="yumi_link_2_r"/>
    <child link="yumi_link_3_r"/>
    <origin rpy="-1.57079632679 0.0 0.0" xyz="-0.03 0.17283 0.0"/>
    <axis xyz="0 0 1"/>
    <limit effort="300" lower="-2.9" upper="2.9" velocity="3.14159265359"/>
    <!--   <safety_controller soft_lower_limit="${-168 * M_PI / 180}"
           soft_upper_limit="${168 * M_PI / 180}"
           k_position="${safety_controller_k_pos}"
           k_velocity="${safety_controller_k_vel}"/> -->
    <dynamics damping="0.5"/>
  </joint>
  <link name="yumi_link_3_r">
    <inertial>
      <origin rpy="0 0 0" xyz="0 0 0"/>
      <mass value="0.2"/>
      <inertia ixx="0.1" ixy="0" ixz="0" iyy="0.1" iyz="0" izz="0.1"/>
    </inertial>
    <visual>
      <origin rpy="0 0 0" xyz="0 0 0"/>
      <geometry>
        <mesh filename="/home/bill/garage/kfp_v2/morpheus/models/yumi_description/meshes/yumi/link_3.stl"/>
      </geometry>
      <material name="Grey"/>
    </visual>
    <collision>
      <origin rpy="0 0 0" xyz="0 0 0"/>
      <geometry>
        <mesh filename="/home/bill/garage/kfp_v2/morpheus/models/yumi_description/meshes/yumi/coarse/link_3.stl"/>
      </geometry>
      <material name="Grey"/>
    </collision>
  </link>
  <!-- joint between link_3_r and link_4_r -->
  <joint name="yumi_joint_3_r" type="revolute">
    <parent link="yumi_link_3_r"/>
    <child link="yumi_link_4_r"/>
    <origin rpy="1.57079632679 -1.57079632679 0.0" xyz="-0.04188 0.0 0.07873"/>
    <axis xyz="0 0 1"/>
    <limit effort="300" lower="-2.1" upper="1.3" velocity="3.14159265359"/>
    <!--   <safety_controller soft_lower_limit="${-168 * M_PI / 180}"
           soft_upper_limit="${168 * M_PI / 180}"
           k_position="${safety_controller_k_pos}"
           k_velocity="${safety_controller_k_vel}"/> -->
    <dynamics damping="0.5"/>
  </joint>
  <link name="yumi_link_4_r">
    <inertial>
      <origin rpy="0 0 0" xyz="0 0 0"/>
      <mass value="0.2"/>
      <inertia ixx="0.1" ixy="0" ixz="0" iyy="0.1" iyz="0" izz="0.1"/>
    </inertial>
    <visual>
      <origin rpy="0 0 0" xyz="0 0 0"/>
      <geometry>
        <mesh filename="/home/bill/garage/kfp_v2/morpheus/models/yumi_description/meshes/yumi/link_4.stl"/>
      </geometry>
      <material name="Grey"/>
    </visual>
    <collision>
      <origin rpy="0 0 0" xyz="0 0 0"/>
      <geometry>
        <mesh filename="/home/bill/garage/kfp_v2/morpheus/models/yumi_description/meshes/yumi/coarse/link_4.stl"/>
      </geometry>
      <material name="Grey"/>
    </collision>
  </link>
  <!-- joint between link_4_r and link_5_r -->
  <joint name="yumi_joint_4_r" type="revolute">
    <parent link="yumi_link_4_r"/>
    <child link="yumi_link_5_r"/>
    <origin rpy="-1.57079632679 0.0 0.0" xyz="0.0405 0.16461 0.0"/>
    <axis xyz="0 0 1"/>
    <limit effort="300" lower="-5.0" upper="5.0" velocity="3.14159265359"/>
    <!--   <safety_controller soft_lower_limit="${-168 * M_PI / 180}"
           soft_upper_limit="${168 * M_PI / 180}"
           k_position="${safety_controller_k_pos}"
           k_velocity="${safety_controller_k_vel}"/> -->
    <dynamics damping="0.5"/>
  </joint>
  <link name="yumi_link_5_r">
    <inertial>
      <origin rpy="0 0 0" xyz="0 0 0"/>
      <mass value="0.2"/>
      <inertia ixx="0.1" ixy="0" ixz="0" iyy="0.1" iyz="0" izz="0.1"/>
    </inertial>
    <visual>
      <origin rpy="0 0 0" xyz="0 0 0"/>
      <geometry>
        <mesh filename="/home/bill/garage/kfp_v2/morpheus/models/yumi_description/meshes/yumi/link_5.stl"/>
      </geometry>
      <material name="Grey"/>
    </visual>
    <collision>
      <origin rpy="0 0 0" xyz="0 0 0"/>
      <geometry>
        <mesh filename="/home/bill/garage/kfp_v2/morpheus/models/yumi_description/meshes/yumi/coarse/link_5.stl"/>
      </geometry>
      <material name="Grey"/>
    </collision>
  </link>
  <!-- joint between link_5_r and link_6_r -->
  <joint name="yumi_joint_5_r" type="revolute">
    <parent link="yumi_link_5_r"/>
    <child link="yumi_link_6_r"/>
    <origin rpy="1.57079632679 0.0 0.0" xyz="-0.027 0 0.10039"/>
    <axis xyz="0 0 1"/>
    <limit effort="300" lower="-1.25" upper="2.25" velocity="3.14159265359"/>
    <!--   <safety_controller soft_lower_limit="${-168 * M_PI / 180}"
           soft_upper_limit="${168 * M_PI / 180}"
           k_position="${safety_controller_k_pos}"
           k_velocity="${safety_controller_k_vel}"/> -->
    <dynamics damping="0.5"/>
  </joint>
  <link name="yumi_link_6_r">
    <inertial>
      <origin rpy="0 0 0" xyz="0 0 0"/>
      <mass value="0.2"/>
      <inertia ixx="0.1" ixy="0" ixz="0" iyy="0.1" iyz="0" izz="0.1"/>
    </inertial>
    <visual>
      <origin rpy="0 0 0" xyz="0 0 0"/>
      <geometry>
        <mesh filename="/home/bill/garage/kfp_v2/morpheus/models/yumi_description/meshes/yumi/link_6.stl"/>
      </geometry>
      <material name="Grey"/>
    </visual>
    <collision>
      <origin rpy="0 0 0" xyz="0 0 0"/>
      <geometry>
        <mesh filename="/home/bill/garage/kfp_v2/morpheus/models/yumi_description/meshes/yumi/coarse/link_6.stl"/>
      </geometry>
      <material name="Grey"/>
    </collision>
  </link>
  <!-- joint between link_6_r and link_7_r -->
  <joint name="yumi_joint_6_r" type="revolute">
    <parent link="yumi_link_6_r"/>
    <child link="yumi_link_7_r"/>
    <origin rpy="-1.57079632679 0.0 0.0" xyz="0.027 0.029 0.0"/>
    <axis xyz="0 0 1"/>
    <limit effort="300" lower="-3.9" upper="3.9" velocity="3.14159265359"/>
    <!--   <safety_controller soft_lower_limit="${-168 * M_PI / 180}"
           soft_upper_limit="${168 * M_PI / 180}"
           k_position="${safety_controller_k_pos}"
           k_velocity="${safety_controller_k_vel}"/> -->
    <dynamics damping="0.5"/>
  </joint>
  <link name="yumi_link_7_r">
    <inertial>
      <origin rpy="0 0 0" xyz="0 0 0"/>
      <mass value="0.2"/>
      <inertia ixx="0.1" ixy="0" ixz="0" iyy="0.1" iyz="0" izz="0.1"/>
    </inertial>
    <visual>
      <origin rpy="0 0 0" xyz="0 0 0"/>
      <geometry>
        <mesh filename="/home/bill/garage/kfp_v2/morpheus/models/yumi_description/meshes/yumi/link_7.stl"/>
      </geometry>
      <material name="Grey"/>
    </visual>
    <collision>
      <origin rpy="0 0 0" xyz="0 0 0"/>
      <geometry>
        <mesh filename="/home/bill/garage/kfp_v2/morpheus/models/yumi_description/meshes/yumi/coarse/link_7.stl"/>
      </geometry>
      <material name="Grey"/>
    </collision>
  </link>
  <!--///////////////////////////////////// LEFT ARM ////////////////////////////////  -->
  <!-- joint between body and link_1_l -->
  <joint name="yumi_joint_1_l" type="revolute">
    <parent link="yumi_body"/>
    <child link="yumi_link_1_l"/>
    <origin rpy="0.9781 -0.5716 2.3180" xyz="0.05355 0.07250 0.41492"/>
    <axis xyz="0 0 1"/>
    <limit effort="300" lower="-2.8" upper="2.8" velocity="3.14159265359"/>
    <!--   <safety_controller soft_lower_limit="${-168 * M_PI / 180}"
           soft_upper_limit="${168 * M_PI / 180}"
           k_position="${safety_controller_k_pos}"
           k_velocity="${safety_controller_k_vel}"/> -->
    <dynamics damping="0.5"/>
  </joint>
  <link name="yumi_link_1_l">
    <inertial>
      <origin rpy="0 0 0" xyz="0 -0.03 0.12"/>
      <mass value="0.2"/>
      <inertia ixx="0.1" ixy="0" ixz="0" iyy="0.1" iyz="0" izz="0.1"/>
    </inertial>
    <visual>
      <origin rpy="0 0 0" xyz="0 0 0"/>
      <geometry>
        <mesh filename="/home/bill/garage/kfp_v2/morpheus/models/yumi_description/meshes/yumi/link_1.stl"/>
      </geometry>
      <material name="Grey"/>
    </visual>
    <collision>
      <origin rpy="0 0 0" xyz="0 0 0"/>
      <geometry>
        <mesh filename="/home/bill/garage/kfp_v2/morpheus/models/yumi_description/meshes/yumi/coarse/link_1.stl"/>
      </geometry>
      <material name="Grey"/>
    </collision>
  </link>
  <!-- joint between link_1_l and link_2_l -->
  <joint name="yumi_joint_2_l" type="revolute">
    <parent link="yumi_link_1_l"/>
    <child link="yumi_link_2_l"/>
    <origin rpy="1.57079632679 0.0 0.0" xyz="0.03 0.0 0.1"/>
    <axis xyz="0 0 1"/>
    <limit effort="300" lower="-2.4" upper="0.74" velocity="3.14159265359"/>
    <!--   <safety_controller soft_lower_limit="${-168 * M_PI / 180}"
           soft_upper_limit="${168 * M_PI / 180}"
           k_position="${safety_controller_k_pos}"
           k_velocity="${safety_controller_k_vel}"/> -->
    <dynamics damping="0.5"/>
  </joint>
  <link name="yumi_link_2_l">
    <inertial>
      <origin rpy="0 0 0" xyz="0 0 0"/>
      <mass value="0.2"/>
      <inertia ixx="0.1" ixy="0" ixz="0" iyy="0.1" iyz="0" izz="0.1"/>
    </inertial>
    <visual>
      <origin rpy="0 0 0" xyz="0 0 0"/>
      <geometry>
        <mesh filename="/home/bill/garage/kfp_v2/morpheus/models/yumi_description/meshes/yumi/link_2.stl"/>
      </geometry>
      <material name="Grey"/>
    </visual>
    <collision>
      <origin rpy="0 0 0" xyz="0 0 0"/>
      <geometry>
        <mesh filename="/home/bill/garage/kfp_v2/morpheus/models/yumi_description/meshes/yumi/coarse/link_2.stl"/>
      </geometry>
      <material name="Grey"/>
    </collision>
  </link>
  <!-- joint between link_2_l and link_3_l -->
  <joint name="yumi_joint_7_l" type="revolute">
    <parent link="yumi_link_2_l"/>
    <child link="yumi_link_3_l"/>
    <origin rpy="-1.57079632679 0.0 0.0" xyz="-0.03 0.17283 0.0"/>
    <axis xyz="0 0 1"/>
    <limit effort="300" lower="-2.9" upper="2.9" velocity="3.14159265359"/>
    <!--   <safety_controller soft_lower_limit="${-168 * M_PI / 180}"
           soft_upper_limit="${168 * M_PI / 180}"
           k_position="${safety_controller_k_pos}"
           k_velocity="${safety_controller_k_vel}"/> -->
    <dynamics damping="0.5"/>
  </joint>
  <link name="yumi_link_3_l">
    <inertial>
      <origin rpy="0 0 0" xyz="0 0 0"/>
      <mass value="0.2"/>
      <inertia ixx="0.1" ixy="0" ixz="0" iyy="0.1" iyz="0" izz="0.1"/>
    </inertial>
    <visual>
      <origin rpy="0 0 0" xyz="0 0 0"/>
      <geometry>
        <mesh filename="/home/bill/garage/kfp_v2/morpheus/models/yumi_description/meshes/yumi/link_3.stl"/>
      </geometry>
      <material name="Grey"/>
    </visual>
    <collision>
      <origin rpy="0 0 0" xyz="0 0 0"/>
      <geometry>
        <mesh filename="/home/bill/garage/kfp_v2/morpheus/models/yumi_description/meshes/yumi/coarse/link_3.stl"/>
      </geometry>
      <material name="Grey"/>
    </collision>
  </link>
  <!-- joint between link_3_l and link_4_l -->
  <joint name="yumi_joint_3_l" type="revolute">
    <parent link="yumi_link_3_l"/>
    <child link="yumi_link_4_l"/>
    <origin rpy="1.57079632679 -1.57079632679 0.0" xyz="-0.04188 0.0 0.07873"/>
    <axis xyz="0 0 1"/>
    <limit effort="300" lower="-2.1" upper="1.3" velocity="3.14159265359"/>
    <!--   <safety_controller soft_lower_limit="${-168 * M_PI / 180}"
           soft_upper_limit="${168 * M_PI / 180}"
           k_position="${safety_controller_k_pos}"
           k_velocity="${safety_controller_k_vel}"/> -->
    <dynamics damping="0.5"/>
  </joint>
  <link name="yumi_link_4_l">
    <inertial>
      <origin rpy="0 0 0" xyz="0 0 0"/>
      <mass value="0.2"/>
      <inertia ixx="0.1" ixy="0" ixz="0" iyy="0.1" iyz="0" izz="0.1"/>
    </inertial>
    <visual>
      <origin rpy="0 0 0" xyz="0 0 0"/>
      <geometry>
        <mesh filename="/home/bill/garage/kfp_v2/morpheus/models/yumi_description/meshes/yumi/link_4.stl"/>
      </geometry>
      <material name="Grey"/>
    </visual>
    <collision>
      <origin rpy="0 0 0" xyz="0 0 0"/>
      <geometry>
        <mesh filename="/home/bill/garage/kfp_v2/morpheus/models/yumi_description/meshes/yumi/coarse/link_4.stl"/>
      </geometry>
      <material name="Grey"/>
    </collision>
  </link>
  <!-- joint between link_4_l and link_5_l -->
  <joint name="yumi_joint_4_l" type="revolute">
    <parent link="yumi_link_4_l"/>
    <child link="yumi_link_5_l"/>
    <origin rpy="-1.57079632679 0.0 0.0" xyz="0.0405 0.16461 0.0"/>
    <axis xyz="0 0 1"/>
    <limit effort="300" lower="-5.0" upper="5.0" velocity="3.14159265359"/>
    <!--   <safety_controller soft_lower_limit="${-168 * M_PI / 180}"
           soft_upper_limit="${168 * M_PI / 180}"
           k_position="${safety_controller_k_pos}"
           k_velocity="${safety_controller_k_vel}"/> -->
    <dynamics damping="0.5"/>
  </joint>
  <link name="yumi_link_5_l">
    <inertial>
      <origin rpy="0 0 0" xyz="0 0 0"/>
      <mass value="0.2"/>
      <inertia ixx="0.1" ixy="0" ixz="0" iyy="0.1" iyz="0" izz="0.1"/>
    </inertial>
    <visual>
      <origin rpy="0 0 0" xyz="0 0 0"/>
      <geometry>
        <mesh filename="/home/bill/garage/kfp_v2/morpheus/models/yumi_description/meshes/yumi/link_5.stl"/>
      </geometry>
      <material name="Grey"/>
    </visual>
    <collision>
      <origin rpy="0 0 0" xyz="0 0 0"/>
      <geometry>
        <mesh filename="/home/bill/garage/kfp_v2/morpheus/models/yumi_description/meshes/yumi/coarse/link_5.stl"/>
      </geometry>
      <material name="Grey"/>
    </collision>
  </link>
  <!-- joint between link_5_l and link_6_l -->
  <joint name="yumi_joint_5_l" type="revolute">
    <parent link="yumi_link_5_l"/>
    <child link="yumi_link_6_l"/>
    <origin rpy="1.57079632679 0.0 0.0" xyz="-0.027 0 0.10039"/>
    <axis xyz="0 0 1"/>
    <limit effort="300" lower="-1.25" upper="2.25" velocity="3.14159265359"/>
    <!--   <safety_controller soft_lower_limit="${-168 * M_PI / 180}"
           soft_upper_limit="${168 * M_PI / 180}"
           k_position="${safety_controller_k_pos}"
           k_velocity="${safety_controller_k_vel}"/> -->
    <dynamics damping="0.5"/>
  </joint>
  <link name="yumi_link_6_l">
    <inertial>
      <origin rpy="0 0 0" xyz="0 0 0"/>
      <mass value="0.2"/>
      <inertia ixx="0.1" ixy="0" ixz="0" iyy="0.1" iyz="0" izz="0.1"/>
    </inertial>
    <visual>
      <origin rpy="0 0 0" xyz="0 0 0"/>
      <geometry>
        <mesh filename="/home/bill/garage/kfp_v2/morpheus/models/yumi_description/meshes/yumi/link_6.stl"/>
      </geometry>
      <material name="Grey"/>
    </visual>
    <collision>
      <origin rpy="0 0 0" xyz="0 0 0"/>
      <geometry>
        <mesh filename="/home/bill/garage/kfp_v2/morpheus/models/yumi_description/meshes/yumi/coarse/link_6.stl"/>
      </geometry>
      <material name="Grey"/>
    </collision>
  </link>
  <!-- joint between link_6_l and link_7_l -->
  <joint name="yumi_joint_6_l" type="revolute">
    <parent link="yumi_link_6_l"/>
    <child link="yumi_link_7_l"/>
    <origin rpy="-1.57079632679 0.0 0.0" xyz="0.027 0.029 0.0"/>
    <axis xyz="0 0 1"/>
    <limit effort="300" lower="-3.9" upper="3.9" velocity="3.14159265359"/>
    <!--   <safety_controller soft_lower_limit="${-168 * M_PI / 180}"
           soft_upper_limit="${168 * M_PI / 180}"
           k_position="${safety_controller_k_pos}"
           k_velocity="${safety_controller_k_vel}"/> -->
    <dynamics damping="0.5"/>
  </joint>
  <link name="yumi_link_7_l">
    <inertial>
      <origin rpy="0 0 0" xyz="0 0 0"/>
      <mass value="0.2"/>
      <inertia ixx="0.1" ixy="0" ixz="0" iyy="0.1" iyz="0" izz="0.1"/>
    </inertial>
    <visual>
      <origin rpy="0 0 0" xyz="0 0 0"/>
      <geometry>
        <mesh filename="/home/bill/garage/kfp_v2/morpheus/models/yumi_description/meshes/yumi/link_7.stl"/>
      </geometry>
      <material name="Grey"/>
    </visual>
    <collision>
      <origin rpy="0 0 0" xyz="0 0 0"/>
      <geometry>
        <mesh filename="/home/bill/garage/kfp_v2/morpheus/models/yumi_description/meshes/yumi/coarse/link_7.stl"/>
      </geometry>
      <material name="Grey"/>
    </collision>
  </link>
  <!-- body -->
  <gazebo reference="yumi_body">
    <material>Gazebo/Ivory</material>
    <mu1>0.2</mu1>
    <mu2>0.2</mu2>
  </gazebo>
  <!-- <xacro:yumi_transmission name="${name}" hardware_interface="${hardware_interface}"/> -->
  <!--joint between {parent} and base-->
  <joint name="yumi_link_7_r_joint" type="fixed">
    <origin rpy="0 0 3.14159265359" xyz="0 0 0.007"/>
    <parent link="yumi_link_7_r"/>
    <child link="gripper_r_base"/>
  </joint>
  <link name="gripper_r_base">
    <inertial>
      <origin rpy="0 0 0" xyz="0 0 0"/>
      <mass value="0.2"/>
      <inertia ixx="0.0001" ixy="0" ixz="0" iyy="0.0001" iyz="0" izz="0.0001"/>
    </inertial>
    <visual>
      <origin rpy="0 0 0" xyz="0 0 0"/>
      <geometry>
        <mesh filename="/home/bill/garage/kfp_v2/morpheus/models/yumi_description/meshes/gripper/base.stl"/>
      </geometry>
      <material name="Light_Grey"/>
    </visual>
    <collision>
      <origin rpy="0 0 0" xyz="0 0 0"/>
      <geometry>
        <mesh filename="/home/bill/garage/kfp_v2/morpheus/models/yumi_description/meshes/gripper/coarse/base.stl"/>
      </geometry>
      <material name="Light_Grey"/>
    </collision>
  </link>
  <!-- joint between base and right finger -->
  <joint name="gripper_r_joint" type="prismatic">
    <parent link="gripper_r_base"/>
    <child link="gripper_r_finger_r"/>
    <origin rpy="0 0 0" xyz="0 -0.0065 0.0837"/>
    <axis xyz="-1 0 0"/>
    <limit effort="300" lower="0" upper="0.025" velocity="0.02"/>
    <!--   <safety_controller soft_lower_limit="${-168 * M_PI / 180}"
           soft_upper_limit="${168 * M_PI / 180}"
           k_position="${safety_controller_k_pos}"
           k_velocity="${safety_controller_k_vel}"/> -->
    <dynamics damping="0.5"/>
  </joint>
  <link name="gripper_r_finger_r">
    <inertial>
      <origin rpy="0 0 0" xyz="0 0 0"/>
      <mass value="0.01"/>
      <inertia ixx="0.000001" ixy="0" ixz="0" iyy="0.000001" iyz="0" izz="0.000001"/>
    </inertial>
    <visual>
      <origin rpy="0 0 0" xyz="0 0 0"/>
      <geometry>
        <mesh filename="/home/bill/garage/kfp_v2/morpheus/models/yumi_description/meshes/gripper/finger.stl"/>
      </geometry>
      <material name="Grey"/>
    </visual>
    <collision>
      <origin rpy="0 0 0" xyz="0 0 0"/>
      <geometry>
        <mesh filename="/home/bill/garage/kfp_v2/morpheus/models/yumi_description/meshes/gripper/coarse/finger.stl"/>
      </geometry>
      <material name="Grey"/>
    </collision>
  </link>
  <!-- joint between base and left finger -->
  <joint name="gripper_r_joint_m" type="prismatic">
    <parent link="gripper_r_base"/>
    <child link="gripper_r_finger_l"/>
    <origin rpy="0 0 3.14159265359" xyz="0 0.0065 0.0837"/>
    <axis xyz="-1 0 0"/>
    <limit effort="300" lower="0" upper="0.025" velocity="0.02"/>
    <!--   <safety_controller soft_lower_limit="${-168 * M_PI / 180}"
           soft_upper_limit="${168 * M_PI / 180}"
           k_position="${safety_controller_k_pos}"
           k_velocity="${safety_controller_k_vel}"/> -->
    <dynamics damping="0.5"/>
    <mimic joint="gripper_r_joint"/>
  </joint>
  <link name="gripper_r_finger_l">
    <inertial>
      <origin rpy="0 0 0" xyz="0 0 0"/>
      <mass value="0.01"/>
      <inertia ixx="0.000001" ixy="0" ixz="0" iyy="0.000001" iyz="0" izz="0.000001"/>
    </inertial>
    <visual>
      <origin rpy="0 0 0" xyz="0 0 0"/>
      <geometry>
        <mesh filename="/home/bill/garage/kfp_v2/morpheus/models/yumi_description/meshes/gripper/finger.stl"/>
      </geometry>
      <material name="Grey"/>
    </visual>
    <collision>
      <origin rpy="0 0 0" xyz="0 0 0"/>
      <geometry>
        <mesh filename="/home/bill/garage/kfp_v2/morpheus/models/yumi_description/meshes/gripper/coarse/finger.stl"/>
      </geometry>
      <material name="Grey"/>
    </collision>
  </link>
  <!-- Plugin for the mimic o/c joint - AFAIK, that shouldn't be necessary any more starting with Gazebo 3.0 -->
  <gazebo>
    <plugin filename="libgazebo_mimic_plugin.so" name="mimic_plugin">
      <joint>gripper_r_joint</joint>
      <mimicJoint>gripper_r_joint_m</mimicJoint>
      <multiplier>1.0</multiplier>
    </plugin>
  </gazebo>
  <!-- body -->
  <gazebo reference="gripper_r_base">
    <material>Gazebo/Light_Grey</material>
    <mu1>0.2</mu1>
    <mu2>0.2</mu2>
  </gazebo>
  <transmission name="gripper_r_tran">
    <type>transmission_interface/SimpleTransmission</type>
    <joint name="gripper_r_joint">
      <hardwareInterface>PositionJointInferface</hardwareInterface>
    </joint>
    <actuator name="gripper_r_motor">
      <hardwareInterface>PositionJointInferface</hardwareInterface>
      <mechanicalReduction>1</mechanicalReduction>
    </actuator>
  </transmission>
  <!--joint between {parent} and base-->
  <joint name="yumi_link_7_l_joint" type="fixed">
    <origin rpy="0 0 3.14159265359" xyz="0 0 0.007"/>
    <parent link="yumi_link_7_l"/>
    <child link="gripper_l_base"/>
  </joint>
  <link name="gripper_l_base">
    <inertial>
      <origin rpy="0 0 0" xyz="0 0 0"/>
      <mass value="0.2"/>
      <inertia ixx="0.0001" ixy="0" ixz="0" iyy="0.0001" iyz="0" izz="0.0001"/>
    </inertial>
    <visual>
      <origin rpy="0 0 0" xyz="0 0 0"/>
      <geometry>
        <mesh filename="/home/bill/garage/kfp_v2/morpheus/models/yumi_description/meshes/gripper/base.stl"/>
      </geometry>
      <material name="Light_Grey"/>
    </visual>
    <collision>
      <origin rpy="0 0 0" xyz="0 0 0"/>
      <geometry>
        <mesh filename="/home/bill/garage/kfp_v2/morpheus/models/yumi_description/meshes/gripper/coarse/base.stl"/>
      </geometry>
      <material name="Light_Grey"/>
    </collision>
  </link>
  <!-- joint between base and right finger -->
  <joint name="gripper_l_joint" type="prismatic">
    <parent link="gripper_l_base"/>
    <child link="gripper_l_finger_r"/>
    <origin rpy="0 0 0" xyz="0 -0.0065 0.0837"/>
    <axis xyz="-1 0 0"/>
    <limit effort="300" lower="0" upper="0.025" velocity="0.02"/>
    <!--   <safety_controller soft_lower_limit="${-168 * M_PI / 180}"
           soft_upper_limit="${168 * M_PI / 180}"
           k_position="${safety_controller_k_pos}"
           k_velocity="${safety_controller_k_vel}"/> -->
    <dynamics damping="0.5"/>
  </joint>
  <link name="gripper_l_finger_r">
    <inertial>
      <origin rpy="0 0 0" xyz="0 0 0"/>
      <mass value="0.01"/>
      <inertia ixx="0.000001" ixy="0" ixz="0" iyy="0.000001" iyz="0" izz="0.000001"/>
    </inertial>
    <visual>
      <origin rpy="0 0 0" xyz="0 0 0"/>
      <geometry>
        <mesh filename="/home/bill/garage/kfp_v2/morpheus/models/yumi_description/meshes/gripper/finger.stl"/>
      </geometry>
      <material name="Grey"/>
    </visual>
    <collision>
      <origin rpy="0 0 0" xyz="0 0 0"/>
      <geometry>
        <mesh filename="/home/bill/garage/kfp_v2/morpheus/models/yumi_description/meshes/gripper/coarse/finger.stl"/>
      </geometry>
      <material name="Grey"/>
    </collision>
  </link>
  <!-- joint between base and left finger -->
  <joint name="gripper_l_joint_m" type="prismatic">
    <parent link="gripper_l_base"/>
    <child link="gripper_l_finger_l"/>
    <origin rpy="0 0 3.14159265359" xyz="0 0.0065 0.0837"/>
    <axis xyz="-1 0 0"/>
    <limit effort="300" lower="0" upper="0.025" velocity="0.02"/>
    <!--   <safety_controller soft_lower_limit="${-168 * M_PI / 180}"
           soft_upper_limit="${168 * M_PI / 180}"
           k_position="${safety_controller_k_pos}"
           k_velocity="${safety_controller_k_vel}"/> -->
    <dynamics damping="0.5"/>
    <mimic joint="gripper_l_joint"/>
  </joint>
  <link name="gripper_l_finger_l">
    <inertial>
      <origin rpy="0 0 0" xyz="0 0 0"/>
      <mass value="0.01"/>
      <inertia ixx="0.000001" ixy="0" ixz="0" iyy="0.000001" iyz="0" izz="0.000001"/>
    </inertial>
    <visual>
      <origin rpy="0 0 0" xyz="0 0 0"/>
      <geometry>
        <mesh filename="/home/bill/garage/kfp_v2/morpheus/models/yumi_description/meshes/gripper/finger.stl"/>
      </geometry>
      <material name="Grey"/>
    </visual>
    <collision>
      <origin rpy="0 0 0" xyz="0 0 0"/>
      <geometry>
        <mesh filename="/home/bill/garage/kfp_v2/morpheus/models/yumi_description/meshes/gripper/coarse/finger.stl"/>
      </geometry>
      <material name="Grey"/>
    </collision>
  </link>

</robot>
