<robot name="buff_digit" >
<material name="black">
    <color rgba="0.2 0.2 0.2 1.0"/>
  </material>
  <material name="blue">
    <color rgba="1.0 1.0 1.0 1.0"/>
  </material>
  <material name="green">
    <color rgba="1.0 1.0 1.0 1.0"/>
  </material>
  <material name="grey">
    <color rgba="0.4 0.4 0.4 1.0"/>
  </material>
  <material name="silver">
    <color rgba="0.913725490196 0.913725490196 0.847058823529 1.0"/>
  </material>
  <material name="orange">
    <color rgba="1.0 1.0 1.0 1.0"/>
  </material>
  <material name="brown">
    <color rgba="0.870588235294 0.811764705882 0.764705882353 1.0"/>
  </material>
  <material name="red">
    <color rgba="1.0 1.0 1.0 1.0"/>
  </material>
  <material name="white">
    <color rgba="1.0 1.0 1.0 1.0"/>
  </material>
  <material name="scarlet">
    <color rgba="0.28 0.82 0.8 1"/>
  </material>


 <link name="left_shoulder_roll">
    <inertial>
      <origin rpy="0 0 0" xyz="9e-06 -0.003158 0.023405"/>
      <mass value="0.535396"/>
      <inertia ixx="0.000704" ixy="1.4e-05" ixz="1.2e-05" iyy="0.00075" iyz="3.5e-05" izz="0.000298"/>
    </inertial>
    <visual>
      <origin rpy="0 0 0" xyz="0 0 0"/>
      <geometry>
        <mesh filename="stl/arm-L1.stl"/>
      </geometry>
      <material name="grey">
        <color rgba="0.35 0.35 0.35 1"/>
      </material>
    </visual>
    <collision>
      <origin rpy="0 0 0" xyz="0 0 0"/>
      <geometry>
        <mesh filename="stl/arm-L1.stl"/>
      </geometry>
    </collision>
  </link>
  <link name="left_shoulder_pitch">
    <inertial>
      <origin rpy="0 0 0" xyz="-4.2e-05 -0.061882 -0.073788"/>
      <mass value="1.440357"/>
      <inertia ixx="0.006761" ixy="-6e-06" ixz="-3e-06" iyy="0.002087" iyz="-0.002046" izz="0.005778"/>
    </inertial>
    <visual>
      <origin rpy="0 0 0" xyz="0 0 0"/>
      <geometry>
        <mesh filename="stl/arm-L2.stl"/>
      </geometry>
      <material name="scarlet">
        <color rgba="0.89 0.13 0.0 1"/>
      </material>
    </visual>
    <collision>
      <origin rpy="0 0 0" xyz="0 0 0"/>
      <geometry>
        <mesh filename="stl/arm-L2.stl"/>
      </geometry>
    </collision>
  </link>
  <link name="left_shoulder_yaw">
    <inertial>
      <origin rpy="0 0 0" xyz="-3e-05 -0.001937 0.11407"/>
      <mass value="1.065387"/>
      <inertia ixx="0.006967" ixy="1e-06" ixz="-1e-06" iyy="0.007003" iyz="1.5e-05" izz="0.000673"/>
    </inertial>
    <visual>
      <origin rpy="0 0 0" xyz="0 0 0"/>
      <geometry>
        <mesh filename="stl/arm-L3.stl"/>
      </geometry>
      <material name="grey">
        <color rgba="0.35 0.35 0.35 1"/>
      </material>
    </visual>
    <collision>
      <origin rpy="0 0 0" xyz="0 0 0"/>
      <geometry>
        <mesh filename="stl/arm-L3.stl"/>
      </geometry>
    </collision>
  </link>
  <link name="left_elbow">
    <inertial>
      <origin rpy="0 0 0" xyz="0.107996 -0.000521 -0.017765"/>
      <mass value="0.550582"/>
      <inertia ixx="0.000476" ixy="2.9e-05" ixz="0.001403" iyy="0.009564" iyz="1.5e-05" izz="-9e-06"/>
    </inertial>
    <visual>
      <origin rpy="0 0 0" xyz="0 0 0"/>
      <geometry>
        <mesh filename="stl/arm-L4.stl"/>
      </geometry>
      <material name="light_grey">
        <color rgba="0.75 0.75 0.75 1"/>
      </material>
    </visual>
    <collision>
      <origin rpy="0 0 0" xyz="0 0 0"/>
      <geometry>
        <mesh filename="stl/arm-L4.stl"/>
      </geometry>
    </collision>
  </link>

<link name="footprint"/>
<joint name="footprint_to_torso" type="fixed">
	<parent link="footprint"/>
    <child link="torso"/>
</joint>
<link name="torso">
	<inertial>
      <origin rpy="0 0 0" xyz="0.107996 -0.000521 -0.017765"/>
      <mass value="0.550582"/>
      <inertia ixx="0.000476" ixy="2.9e-05" ixz="0.001403" iyy="0.009564" iyz="1.5e-05" izz="-9e-06"/>
    </inertial>
    <visual>
      <origin rpy="0 0 0" xyz="0 0 0"/>
      <geometry>
        <box size="0.01 0.01 0.01"/>
      </geometry>
      <material name="light_grey">
        <color rgba="0.75 0.75 0.75 1"/>
      </material>
    </visual>
    <collision>
      <origin rpy="0 0 0" xyz="0 0 0"/>
      <geometry>
        <box size="0.01 0.01 0.01"/>
      </geometry>
    </collision>
</link>


<joint name="shoulder_roll_joint_left" type="continuous">
    <!-- <origin rpy="-1.57079632679 -1.3962633 1.57079632679" xyz="-0.001 0.12 0.4"/> -->
    <origin rpy="0 0 0" xyz="0 0 0"/>
    <axis xyz="0 0 1"/>
    <parent link="torso"/>
    <child link="left_shoulder_roll"/>
    <limit effort="1.4" lower="-1.309" upper="1.309" velocity="12.5"/>
  </joint>
  <joint name="shoulder_pitch_joint_left" type="continuous">
    <origin rpy="1.57079632679 0.785398163397 -0.2792527" xyz="-0.00317 -0.011055 0.0555"/>
    <axis xyz="0 0 -1"/>
    <parent link="left_shoulder_roll"/>
    <child link="left_shoulder_pitch"/>
    <limit effort="1.4" lower="-3.1415" upper="3.1415" velocity="12.5"/>
  </joint>
  <joint name="shoulder_yaw_joint_left" type="continuous">
    <origin rpy="1.57079632679 0 0" xyz="0 -0.165 -0.1"/>
    <axis xyz="0 0 1"/>
    <parent link="left_shoulder_pitch"/>
    <child link="left_shoulder_yaw"/>
    <limit effort="1.4" lower="-1.7453" upper="1.7453" velocity="10"/>
  </joint>
  <joint name="elbow_joint_left" type="continuous">
    <origin rpy="1.57079632679 -0.3926991 0" xyz="0 -0.0385 0.185"/>
    <axis xyz="0 0 1"/>
    <parent link="left_shoulder_yaw"/>
    <child link="left_elbow"/>
    <limit effort="1.4" lower="-1.3526" upper="1.3526" velocity="12.5"/>
  </joint>





  <link name="left_wrist">
    <inertial>
      <origin rpy="0 0 0" xyz="0.107996 0.000521 -0.017765"/>
      <mass value="0.550582"/>
      <inertia ixx="0.000476" ixy="-2.9e-05" ixz="0.001403" iyy="0.009564" iyz="-1.5e-05" izz="-9e-06"/>
    </inertial>
    <visual>
      <origin rpy="0 1.5707 1.5707 " xyz="0 0 0"/>
      <geometry>
        <cylinder radius="0.025" length="0.05"/>
      </geometry>
      <material name="blue">
        <color rgba="0.05 0.05 0.75 0.9"/>
      </material>
    </visual>
    <collision>
      <origin rpy="0 1.5707 1.5707" xyz="0 0 0"/>
      <geometry>
        <cylinder radius="0.025" length="0.05"/>
      </geometry>
    </collision>
  </link>
  <joint name="left_wrist_joint" type="revolute">
    <origin rpy="-1.57079632679 0.1926991 0" xyz="0.38 -0.0 -0.06"/>
    <parent link="left_elbow"/>
    <child link="left_wrist"/>
    <axis xyz="0 1 0"/>
    <limit effort="0" lower="-1.57" upper="1.57" velocity="10"/>
  </joint>

  <link name="gripper_l_base">
    <inertial>
      <origin rpy="0 0 0" xyz="0 0 0"/>
      <mass value="0.2"/>
      <inertia ixx="0.0001" ixy="0" ixz="0" iyy="0.0001" iyz="0" izz="0.0001"/>
    </inertial>
    <visual>
      <origin rpy="0 1.5707 0" xyz="0 0 0"/>
      <geometry>
        <mesh filename="/home/bill/garage/kfp_v2/morpheus/models/yumi_description/meshes/gripper/base.stl"/>
      </geometry>
      <material name="Light_Grey"/>
    </visual>
    <collision>
      <origin rpy="0 1.5707 0" xyz="0 0 0"/>
      <geometry>
        <mesh filename="/home/bill/garage/kfp_v2/morpheus/models/yumi_description/meshes/gripper/coarse/base.stl"/>
      </geometry>
      <material name="Light_Grey"/>
    </collision>
  </link>

  <joint name="gripper_left_wrist_joint" type="revolute">
    <origin rpy="0 0 0" xyz="0.02 0 0"/>
    <parent link="left_wrist"/>
    <child link="gripper_l_base"/>
    <axis xyz="1 0 0"/>
    <limit effort="0" lower="-1.57" upper="1.57" velocity="10"/>
  </joint>

  <link name="left_gripper_ee"/>
  <joint name="left_ee_to_gripper_base" type="fixed">
    <origin rpy="0 0 0" xyz="0.09 0.0 0.0"/>
    <parent link="gripper_l_base"/>
    <child link="left_gripper_ee"/>
  </joint>

  <joint name="gripper_l_joint" type="prismatic">
    <parent link="left_gripper_ee"/>
    <child link="gripper_l_finger_r"/>
    <origin rpy="0 1.57 0" xyz="0.0 -0.0065 0.0"/>
    <axis xyz="-1 0 0"/>
    <limit effort="300" lower="0" upper="0.025" velocity="0.02"/>
    <dynamics damping="0.5"/>
  </joint>
  <link name="gripper_l_finger_r">
    <inertial>
      <origin rpy="0 0 0" xyz="0 0 0"/>
      <mass value="0.01"/>
      <inertia ixx="0.000001" ixy="0" ixz="0" iyy="0.000001" iyz="0" izz="0.000001"/>
    </inertial>
    <visual>
      <origin rpy="0 0 0" xyz="0 0 0"/>
      <geometry>
        <mesh filename="/home/bill/garage/kfp_v2/morpheus/models/yumi_description/meshes/gripper/finger.stl"/>
      </geometry>
      <material name="scarlet"/>
    </visual>
    <collision>
      <origin rpy="0 0 0" xyz="0 0 0"/>
      <geometry>
        <mesh filename="/home/bill/garage/kfp_v2/morpheus/models/yumi_description/meshes/gripper/coarse/finger.stl"/>
      </geometry>
      <material name="Grey"/>
    </collision>
  </link>

  <joint name="gripper_l_joint_m" type="prismatic">
      <parent link="left_gripper_ee"/>
      <child link="gripper_l_finger_l"/>
      <origin rpy="0 -1.57 3.14159265359" xyz="0.0 0.0065 0.0"/>
      <axis xyz="-1 0 0"/>
      <limit effort="300" lower="0" upper="0.025" velocity="0.02"/>
      <dynamics damping="0.5"/>
      <mimic joint="gripper_l_joint"/>
    </joint>
    <link name="gripper_l_finger_l">
      <inertial>
        <origin rpy="0 0 0" xyz="0 0 0"/>
        <mass value="0.01"/>
        <inertia ixx="0.000001" ixy="0" ixz="0" iyy="0.000001" iyz="0" izz="0.000001"/>
      </inertial>
      <visual>
        <origin rpy="0 0 0" xyz="0 0 0"/>
        <geometry>
          <mesh filename="/home/bill/garage/kfp_v2/morpheus/models/yumi_description/meshes/gripper/finger.stl"/>
        </geometry>
        <material name="grey"/>
      </visual>
      <collision>
        <origin rpy="0 0 0" xyz="0 0 0"/>
        <geometry>
          <mesh filename="/home/bill/garage/kfp_v2/morpheus/models/yumi_description/meshes/gripper/coarse/finger.stl"/>
        </geometry>
        <material name="Grey"/>
      </collision>
    </link>


  </robot>