<?xml version="0.0" ?>
<robot name="prosthetic" >



<material name="scarlet">
    <color rgba="0.89 0.13 0.0 1"/>
</material>
<material name="grey">
    <color rgba="0.4 0.4 0.4 1.0"/>
</material>
 <material name="silver">
    <color rgba="0.913725490196 0.913725490196 0.847058823529 1.0"/>
  </material>



  <link name="link0"/>
  <joint name="joint0" type="revolute">
    <parent link="link0"/>
    <child link="jlink0"/>
    <origin rpy="0 0 0" xyz="0 0 0"/> 
    <axis xyz="0 0 1"/>
    <limit lower="-3.1415" upper="3.1415" effort="1.4" velocity="0.25"/>
  </joint>

  <link name="jlink0">
    <inertial>
      <origin rpy="0 0 0" xyz="0 0 0"/>
       <mass value=".01"/>
       <inertia ixx="0" ixy="0" ixz="0" iyy="0" iyz="0" izz="0"/>
    </inertial>
    <visual>
      <origin rpy="0 0 0" xyz="0 0 0"/>
      <geometry>
        <cylinder radius="0.025" length="0.025"/>
      </geometry>
       <material name="grey"/>
    </visual>
    <collision>
      <origin rpy="0 0 0" xyz="0 0 0"/>
      <geometry>
        <cylinder radius="0.025" length="0.025"/>
      </geometry>
    </collision>
  </link>

  <link name="link1">
    <inertial>
      <origin rpy="0 0 0" xyz="0 0 0"/>
       <mass value=".000000001"/>
       <inertia ixx="0" ixy="0" ixz="0" iyy="0" iyz="0" izz="0"/>
    </inertial>
    <visual>
      <origin rpy="0 0 0" xyz="0 0 0"/>
      <geometry>
       <!-- <cylinder radius="0.025" length="0.125"/> -->
       <box size = "0.025 0.08 0.025"/>
      </geometry>
       <material name="scarlet"/> 
    </visual>
    <collision>
      <origin rpy="0 0 0" xyz="0 0 0"/>
      <geometry>
       <box size = "0.025 0.08 0.025"/>
      </geometry>
    </collision>
  </link>

  <joint name="joint1f" type="fixed">
    <parent link="jlink0"/>
    <child link="link1"/>
    <origin rpy="0 0 0" xyz="0 0.04 0.00625"/> 
  </joint>

  <link name="jlink1">
    <inertial>
      <origin rpy="0 0 0" xyz="0 0 0"/>
       <mass value=".01"/>
       <inertia ixx="0" ixy="0" ixz="0" iyy="0" iyz="0" izz="0"/>
    </inertial>
    <visual>
      <origin rpy="0 0 0" xyz="0 0 0"/>
      <geometry>
        <cylinder radius="0.025" length="0.025"/>
      </geometry>
       <material name="scarlet"/>
    </visual>
    <collision>
      <origin rpy="0 0 0" xyz="0 0 0"/>
      <geometry>
        <cylinder radius="0.025" length="0.025"/>
      </geometry>
    </collision>
</link>

  <joint name="joint1" type="revolute">
    <parent link="link1"/>
    <child link="jlink1"/>
    <origin rpy="0 0.785398163397 0" xyz="0 0.04 0"/> 
    <axis xyz="0 1 0"/>
    <limit lower="-3.1415" upper="3.1415" effort="1.4" velocity="0.25"/>  
  </joint>

  <link name="link2">
    <inertial>
      <origin rpy="0 0 0" xyz="0 0 0"/>
       <mass value=".000000001"/>
       <inertia ixx="0" ixy="0" ixz="0" iyy="0" iyz="0" izz="0"/>
    </inertial>
    <visual>
      <origin rpy="0 0 0" xyz="0 0 0"/>
      <geometry>
       <cylinder radius="0.03" length="0.2"/>
      </geometry>
       <material name="scarlet"/> 
    </visual>
    <collision>
      <origin rpy="0 0 0" xyz="0 0 0"/>
      <geometry>
       <cylinder radius="0.03" length="0.2"/>
      </geometry>
    </collision>
</link>

<joint name="joint2f" type="fixed">
    <parent link="jlink1"/>
    <child link="link2"/>
    <origin rpy="0 0 0" xyz="0 0  -0.1"/>   
</joint>

<link name="jlink2">
    <inertial>
      <origin rpy="0 0 0" xyz="0 0 0"/>
       <mass value=".01"/>
       <inertia ixx="0" ixy="0" ixz="0" iyy="0" iyz="0" izz="0"/>
    </inertial>
    <visual>
      <origin rpy="0 0 0" xyz="0 0 0"/>
      <geometry>
        <cylinder radius="0.025" length="0.025"/>
      </geometry>
       <material name="grey"/>
    </visual>
    <collision>
      <origin rpy="0 0 0" xyz="0 0 0"/>
      <geometry>
        <cylinder radius="0.025" length="0.025"/>
      </geometry>
    </collision>
</link>

<joint name="joint2" type="revolute">
    <parent link="link2"/>
    <child link="jlink2"/>
    <origin rpy="0 0 0" xyz="0 0 -0.1"/> 
    <axis xyz="0 0 1"/>
    <limit lower="-3.1415" upper="3.1415" effort="1.4" velocity="0.25"/>  
  </joint>

  <link name="link3">
    <inertial>
      <origin rpy="0 0 0" xyz="0 0 0"/>
       <mass value=".000000001"/>
       <inertia ixx="0" ixy="0" ixz="0" iyy="0" iyz="0" izz="0"/>
    </inertial>
    <visual>
      <origin rpy="0 0 0" xyz="0 0 0"/>
      <geometry>
       <cylinder radius="0.03" length="0.2"/>
      </geometry>
       <material name="grey"/> 
    </visual>
    <collision>
      <origin rpy="0 0 0" xyz="0 0 0"/>
      <geometry>
       <cylinder radius="0.03" length="0.2"/>
      </geometry>
    </collision>
</link>

<joint name="joint3f" type="fixed">
    <parent link="jlink2"/>
    <child link="link3"/>
    <origin rpy="0 0 0" xyz="0 0  -0.1035"/>   
</joint>

<link name="jlink3">
    <inertial>
      <origin rpy="0 0 0" xyz="0 0 0"/>
       <mass value=".01"/>
       <inertia ixx="0" ixy="0" ixz="0" iyy="0" iyz="0" izz="0"/>
    </inertial>
    <visual>
      <origin rpy="1.5707 0 0" xyz="0 0 0"/>
      <geometry>
        <cylinder radius="0.025" length="0.025"/>
      </geometry>
       <material name="grey"/>
    </visual>
    <collision>
      <origin rpy="1.5707 0 0" xyz="0 0 0"/>
      <geometry>
        <cylinder radius="0.025" length="0.025"/>
      </geometry>
    </collision>
</link>

<joint name="joint3" type="revolute">
    <parent link="link3"/>
    <child link="jlink3"/>
    <origin rpy="0 -1.06 0" xyz="0 0.025 -0.1"/> 
    <axis xyz="0 1 0"/>
    <limit lower="-3.1415" upper="3.1415" effort="1.4" velocity="0.25"/>  
  </joint>

  <link name="link4">
    <inertial>
      <origin rpy="0 0 0" xyz="0 0 0"/>
       <mass value=".000000001"/>
       <inertia ixx="0" ixy="0" ixz="0" iyy="0" iyz="0" izz="0"/>
    </inertial>
    <visual>
      <origin rpy="0 0 0" xyz="0 0 0"/>
      <geometry>
       <cylinder radius="0.03" length="0.4"/>
      </geometry>
       <material name="silver"/> 
    </visual>
    <collision>
      <origin rpy="0 0 0" xyz="0 0 0"/>
      <geometry>
       <cylinder radius="0.03" length="0.4"/>
      </geometry>
    </collision>
</link>

<joint name="joint4f" type="fixed">
    <parent link="jlink3"/>
    <child link="link4"/>
    <origin rpy="0 0 0" xyz="0 0  -0.2"/>   
</joint>

<link name="left_wrist">
    <inertial>
      <origin rpy="0 0 0" xyz="0.107996 0.000521 -0.017765"/>
      <mass value="0.550582"/>
      <inertia ixx="0.000476" ixy="-2.9e-05" ixz="0.001403" iyy="0.009564" iyz="-1.5e-05" izz="-9e-06"/>
    </inertial>
    <visual>
      <origin rpy="0 1.5707 1.5707 " xyz="0 0 0"/>
      <geometry>
        <cylinder radius="0.025" length="0.05"/>
      </geometry>
      <material name="blue">
        <color rgba="0.05 0.05 0.75 0.9"/>
      </material>
    </visual>
    <collision>
      <origin rpy="0 1.5707 1.5707" xyz="0 0 0"/>
      <geometry>
        <cylinder radius="0.025" length="0.05"/>
      </geometry>
    </collision>
  </link>
  <joint name="left_wrist_joint" type="revolute">
    <origin rpy="0 1.5707 0" xyz="0.0 0.0 -0.22"/>
    <parent link="link4"/>
    <child link="left_wrist"/>
    <axis xyz="0 1 0"/>
    <limit effort="1.4" lower="-1.57" upper="1.57" velocity="10"/>
  </joint>

  <link name="gripper_l_base">
    <inertial>
      <origin rpy="0 0 0" xyz="0 0 0"/>
      <mass value="0.2"/>
      <inertia ixx="0.0001" ixy="0" ixz="0" iyy="0.0001" iyz="0" izz="0.0001"/>
    </inertial>
    <visual>
      <origin rpy="0 1.5707 0" xyz="0 0 0"/>
      <geometry>
        <!-- <mesh filename="/home/bill/garage/kfp_v2/morpheus/models/yumi_description/meshes/gripper/base.stl"/> -->
        <cylinder radius="0.04" length="0.1"/>
      </geometry>
      <material name="Light_Grey"/>
    </visual>
    <collision>
      <origin rpy="0 1.5707 0" xyz="0 0 0"/>
      <geometry>
        <!-- <mesh filename="/home/bill/garage/kfp_v2/morpheus/models/yumi_description/meshes/gripper/coarse/base.stl"/> -->
       <cylinder radius="0.04" length="0.1"/>
      </geometry>
      <material name="Light_Grey"/>
    </collision>
  </link>

  <joint name="gripper_left_wrist_joint" type="revolute">
    <origin rpy="0 0 0" xyz="0.07 0 0"/>
    <parent link="left_wrist"/>
    <child link="gripper_l_base"/>
    <axis xyz="1 0 0"/>
    <limit effort="1.4" lower="-1.57" upper="1.57" velocity="10"/>
  </joint>

  <link name="left_gripper_ee">
    <inertial>
      <origin rpy="0 0 0" xyz="0 0 0"/>
      <mass value="0.2"/>
      <inertia ixx="0.0001" ixy="0" ixz="0" iyy="0.0001" iyz="0" izz="0.0001"/>
    </inertial>
    <visual>
      <origin rpy="0 1.5707 0" xyz="0 0 0"/>
      <geometry>        
       <cylinder radius="0.025" length="0.025"/>
      </geometry>
      <material name="scarlet"/>
    </visual>
    <collision>
      <origin rpy="0 1.5707 0" xyz="0 0 0"/>
      <geometry>
       <cylinder radius="0.025" length="0.025"/>
      </geometry> 
    </collision>
  </link>
  <joint name="left_ee_to_gripper_base" type="fixed">
    <origin rpy="0 0 0" xyz="0.05125 0.0 0"/>
    <parent link="gripper_l_base"/>
    <child link="left_gripper_ee"/>
  </joint>

   



  


</robot>
