<?xml version="0.0" ?>
<robot name="prosthetic" >



<material name="scarlet">
    <color rgba="0.89 0.13 0.0 1"/>
</material>
<material name="grey">
    <color rgba="0.4 0.4 0.4 1.0"/>
</material>
 <material name="silver">
    <color rgba="0.913725490196 0.913725490196 0.847058823529 1.0"/>
  </material>


 

  <link name="right_jlink0">
    <inertial>
      <origin rpy="0 0 0" xyz="0 0 0"/>
       <mass value=".01"/>
       <inertia ixx="0" ixy="0" ixz="0" iyy="0" iyz="0" izz="0"/>
    </inertial>
    <visual>
      <origin rpy="1.5707  0 0" xyz="0 0 0"/>
      <geometry>
        <cylinder radius="0.025" length="0.025"/>
      </geometry>
       <material name="grey"/>
    </visual>
    <collision>
      <origin rpy="1.5707 0 0" xyz="0 0 0"/>
      <geometry>
        <cylinder radius="0.025" length="0.025"/>
      </geometry>
    </collision>
  </link>

  <link name="right_link1">
    <inertial>
      <origin rpy="0 0 0" xyz="0 0 0"/>
       <mass value=".000000001"/>
       <inertia ixx="0" ixy="0" ixz="0" iyy="0" iyz="0" izz="0"/>
    </inertial>
    <visual>
      <origin rpy="1.5707 0 0" xyz="0 0 0"/>
      <geometry>
       <cylinder radius="0.0125" length="0.08"/>
       <!-- <box size = "0.025 0.08 0.025"/> -->
      </geometry>
       <material name="scarlet"/> 
    </visual>
    <collision>
      <origin rpy="1.5707 0 0" xyz="0 0 0"/>
      <geometry>
       <cylinder radius="0.0125" length="0.08"/>
      </geometry>
    </collision>
  </link>

  <joint name="right_joint1f" type="revolute"> 
    <parent link="right_jlink0"/>
    <child link="right_link1"/>
    <origin rpy="0 0 0" xyz="0 -0.04 0.0"/>  
    <axis xyz="0 1 0"/>
    <limit lower="-3.1415" upper="3.1415" effort="1.4" velocity="0.25"/>
  </joint>

  <link name="right_jlink1">
    <inertial>
      <origin rpy="0 0 0" xyz="0 0 0"/>
       <mass value=".01"/>
       <inertia ixx="0" ixy="0" ixz="0" iyy="0" iyz="0" izz="0"/>
    </inertial>
    <visual>
      <origin rpy="0 1.5707 0" xyz="0 0 0"/>
      <geometry>
        <cylinder radius="0.025" length="0.025"/>
      </geometry>
       <material name="grey"/>
    </visual>
    <collision>
      <origin rpy="0 1.5707 0" xyz="0 0 0"/>
      <geometry>
        <cylinder radius="0.025" length="0.025"/>
      </geometry>
    </collision>
</link>

  <joint name="right_joint1" type="revolute">
    <parent link="right_link1"/>
    <child link="right_jlink1"/>
    <origin rpy="0 0 0" xyz="0 -0.04 0"/> 
    <axis xyz="1 0 0"/>
    <limit lower="-3.1415" upper="3.1415" effort="1.4" velocity="0.25"/>  
  </joint>

  <link name="right_link2">
    <inertial>
      <origin rpy="0 0 0" xyz="0 0 0"/>
       <mass value=".000000001"/>
       <inertia ixx="0" ixy="0" ixz="0" iyy="0" iyz="0" izz="0"/>
    </inertial>
    <visual>
      <origin rpy="0 0 0" xyz="0 0 0"/>
      <geometry>
       <!-- <cylinder radius="0.03" length="0.2"/> -->
       <mesh filename="meshes/link2.obj"/>
      </geometry>
       <!-- <material name="scarlet"/>  -->
    </visual>
    <collision>
      <origin rpy="0 0 0" xyz="0 0 0"/>
      <geometry>
       <cylinder radius="0.03" length="0.2"/>
      </geometry>
    </collision>
</link>

<joint name="right_joint2f" type="fixed">
    <parent link="right_jlink1"/>
    <child link="right_link2"/>
    <origin rpy="0 0 0" xyz="0 0  -0.1"/> 
        
</joint>

<link name="right_jlink2">
    <inertial>
      <origin rpy="0 0 0" xyz="0 0 0"/>
       <mass value=".01"/>
       <inertia ixx="0" ixy="0" ixz="0" iyy="0" iyz="0" izz="0"/>
    </inertial>
    <visual>
      <origin rpy="0 0 0" xyz="0 0 0"/>
      <geometry>
        <cylinder radius="0.025" length="0.025"/>
      </geometry>
       <material name="grey"/>
    </visual>
    <collision>
      <origin rpy="0 0 0" xyz="0 0 0"/>
      <geometry>
        <cylinder radius="0.025" length="0.025"/>
      </geometry>
    </collision>
</link>

<joint name="right_joint2" type="fixed">
    <parent link="right_link2"/>
    <child link="right_jlink2"/>
    <origin rpy="0 0 0" xyz="0 0 -0.1"/> 
     
  </joint>

  <link name="right_link3">
    <inertial>
      <origin rpy="0 0 0" xyz="0 0 0"/>
       <mass value=".000000001"/>
       <inertia ixx="0" ixy="0" ixz="0" iyy="0" iyz="0" izz="0"/>
    </inertial>
    <visual>
      <origin rpy="0 0 0" xyz="0 0 0"/>
      <geometry>
       <cylinder radius="0.03" length="0.2"/>
      </geometry>
       <material name="grey"/> 
    </visual>
    <collision>
      <origin rpy="0 0 0" xyz="0 0 0"/>
      <geometry>
       <cylinder radius="0.03" length="0.2"/>
      </geometry>
    </collision>
</link>

<joint name="right_joint3f" type="fixed">
    <parent link="right_jlink2"/>
    <child link="right_link3"/>
    <origin rpy="0 0 0" xyz="0 0  -0.1035"/>   
</joint>

<link name="right_jlink3">
    <inertial>
      <origin rpy="0 0 0" xyz="0 0 0"/>
       <mass value=".01"/>
       <inertia ixx="0" ixy="0" ixz="0" iyy="0" iyz="0" izz="0"/>
    </inertial>
    <visual>
      <origin rpy="0 1.5707 0" xyz="0 0 0"/>
      <geometry>
        <cylinder radius="0.025" length="0.025"/>
      </geometry>
       <material name="scarlet"/>
    </visual>
    <collision>
      <origin rpy="0 1.5707 0" xyz="0 0 0"/>
      <geometry>
        <cylinder radius="0.025" length="0.025"/>
      </geometry>
    </collision>
</link>

<joint name="right_joint3" type="revolute">
    <parent link="right_link3"/>
    <child link="right_jlink3"/>
    <origin rpy="0 0 0" xyz="0 0.0 -0.1"/> 
    <axis xyz="1 0 0"/>
    <limit lower="-3.1415" upper="3.1415" effort="1.4" velocity="0.25"/>  
  </joint>

  <link name="right_link4">
    <inertial>
      <origin rpy="0 0 0" xyz="0 0 0"/>
       <mass value=".000000001"/>
       <inertia ixx="0" ixy="0" ixz="0" iyy="0" iyz="0" izz="0"/>
    </inertial>
    <visual>
      <origin rpy="0 0 0" xyz="0 0 0"/>
      <geometry>
       <cylinder radius="0.03" length="0.4"/>
      </geometry>
       <material name="silver"/> 
    </visual>
    <collision>
      <origin rpy="0 0 0" xyz="0 0 0"/>
      <geometry>
       <cylinder radius="0.03" length="0.4"/>
      </geometry>
    </collision>
</link>

<joint name="right_joint4f" type="fixed">
    <parent link="right_jlink3"/>
    <child link="right_link4"/>
    <origin rpy="0 0 0" xyz="0 0  -0.2"/>   
</joint>

<link name="right_jlink4">
    <inertial>
      <origin rpy="0 0 0" xyz="0.107996 0.000521 -0.017765"/>
      <mass value="0.550582"/>
      <inertia ixx="0.000476" ixy="-2.9e-05" ixz="0.001403" iyy="0.009564" iyz="-1.5e-05" izz="-9e-06"/>
    </inertial>
    <visual>
      <origin rpy="0 0 0 " xyz="0 0 0"/>
      <geometry>
        <cylinder radius="0.025" length="0.025"/>
      </geometry>
      <material name="scarlet"/> 
    </visual>
    <collision>
      <origin rpy="0 0 0" xyz="0 0 0"/>
      <geometry>
        <cylinder radius="0.025" length="0.025"/>
      </geometry>
    </collision>
</link>

<joint name="right_joint4" type="revolute">
    <origin rpy="0 0 0" xyz="0.0 0.0 -0.2"/>
    <parent link="right_link4"/>
    <child link="right_jlink4"/>
    <axis xyz="0 0 1"/>
    <limit effort="1.4" lower="-1.57" upper="1.57" velocity="10"/>
  </joint>

<link name="right_wrist">
    <inertial>
      <origin rpy="0 0 0" xyz="0.107996 0.000521 -0.017765"/>
      <mass value="0.550582"/>
      <inertia ixx="0.000476" ixy="-2.9e-05" ixz="0.001403" iyy="0.009564" iyz="-1.5e-05" izz="-9e-06"/>
    </inertial>
    <visual>
      <origin rpy="0 1.5707 1.5707 " xyz="0 0 0"/>
      <geometry>
        <cylinder radius="0.025" length="0.05"/>
      </geometry>
      <material name="blue">
        <color rgba="0.05 0.05 0.75 0.9"/>
      </material>
    </visual>
    <collision>
      <origin rpy="0 1.5707 1.5707" xyz="0 0 0"/>
      <geometry>
        <cylinder radius="0.025" length="0.05"/>
      </geometry>
    </collision>
  </link>
  <joint name="right_wrist_joint" type="revolute">
    <origin rpy="0 1.5707 0" xyz="0.0 0.0 -0.025"/>
    <parent link="right_jlink4"/>
    <child link="right_wrist"/>
    <axis xyz="0 1 0"/>
    <limit effort="1.4" lower="-1.57" upper="1.57" velocity="10"/>
  </joint>

  <link name="right_gripper_base">
    <inertial>
      <origin rpy="0 0 0" xyz="0 0 0"/>
      <mass value="0.2"/>
      <inertia ixx="0.0001" ixy="0" ixz="0" iyy="0.0001" iyz="0" izz="0.0001"/>
    </inertial>
    <visual>
      <origin rpy="0 1.5707 0" xyz="0 0 0"/>
      <geometry> 
        <cylinder radius="0.04" length="0.1"/>
      </geometry>
      <material name="Light_Grey"/>
    </visual>
    <collision>
      <origin rpy="0 1.5707 0" xyz="0 0 0"/>
      <geometry> 
       <cylinder radius="0.04" length="0.1"/>
      </geometry>
      <material name="Light_Grey"/>
    </collision>
  </link>

  <joint name="gripper_right_wrist_joint" type="revolute">
    <origin rpy="0 0 0" xyz="0.07 0 0"/>
    <parent link="right_wrist"/>
    <child link="right_gripper_base"/>
    <axis xyz="1 0 0"/>
    <limit effort="1.4" lower="-1.57" upper="1.57" velocity="10"/>
  </joint>

  <link name="right_gripper_ee">
    <inertial>
      <origin rpy="0 0 0" xyz="0 0 0"/>
      <mass value="0.2"/>
      <inertia ixx="0.0001" ixy="0" ixz="0" iyy="0.0001" iyz="0" izz="0.0001"/>
    </inertial>
    <visual>
      <origin rpy="0 1.5707 0" xyz="0 0 0"/>
      <geometry>        
       <cylinder radius="0.025" length="0.025"/>
      </geometry>
      <material name="scarlet"/>
    </visual>
    <collision>
      <origin rpy="0 1.5707 0" xyz="0 0 0"/>
      <geometry>
       <cylinder radius="0.025" length="0.025"/>
      </geometry> 
    </collision>
  </link>
  <joint name="right_gripper_baseee_to_gripper_base" type="fixed">
    <origin rpy="0 0 0" xyz="0.05125 0.0 0"/>
    <parent link="right_gripper_base"/>
    <child link="right_gripper_ee"/>
  </joint>

   



  


</robot>
