<?xml version="1.0" encoding="utf-8"?>
<robot name="not_digit">
  <link name="torso">
    <inertial>
      <origin rpy="0 0 0" xyz="0.001637 0.0002 0.259547"/>
      <mass value="15.028392"/>
      <inertia ixx="0.376284" ixy="-8.8e-05" ixz="0.008378" iyy="0.342655" iyz="6.7e-05" izz="0.100648"/>
    </inertial>
    <visual>
      <origin rpy="0 0 0" xyz="0 0 0"/>
      <geometry>
        <mesh filename="stl/torso.stl"/>
      </geometry>
      <material name="scarlet">
        <color rgba="0.89 0.13 0.0 1"/>
      </material>
    </visual>
    <collision>
      <origin rpy="0 0 0" xyz="0 0 0"/>
      <geometry>
        <mesh filename="stl/torso.stl"/>
      </geometry>
    </collision>
  </link>
  <link name="left_hip_roll">
    <inertial>
      <origin rpy="0 0 0" xyz="-0.001967 0.000244 0.031435"/>
      <mass value="0.915088"/>
      <inertia ixx="0.001017" ixy="-3e-06" ixz="1.3e-05" iyy="0.001148" iyz="-4e-06" izz="0.000766"/>
    </inertial>
    <visual>
      <origin rpy="0 0 0" xyz="0 0 0"/>
      <geometry>
        <mesh filename="stl/hip-yaw-housing.stl"/>
      </geometry>
      <material name="grey">
        <color rgba="0.35 0.35 0.35 1"/>
      </material>
    </visual>
    <collision>
      <origin rpy="0 0 0" xyz="0 0 0"/>
      <geometry>
        <mesh filename="stl/hip-yaw-housing.stl"/>
      </geometry>
    </collision>
  </link>
  <link name="left_hip_yaw">
    <inertial>
      <origin rpy="0 0 0" xyz="1e-05 -0.001945 0.042033"/>
      <mass value="0.818753"/>
      <inertia ixx="0.001627" ixy="-1e-06" ixz="2e-06" iyy="0.001929" iyz="5.3e-05" izz="0.00077"/>
    </inertial>
    <visual>
      <origin rpy="0 0 0" xyz="0 0 0"/>
      <geometry>
        <mesh filename="stl/hip-pitch-housing.stl"/>
      </geometry>
      <material name="light_grey">
        <color rgba="0.75 0.75 0.75 1"/>
      </material>
    </visual>
     <collision>
      <origin rpy="0 0 0" xyz="0 0 0"/>
      <geometry>
        <mesh filename="stl/hip-pitch-housing.stl"/>
      </geometry>
    </collision>
  </link>
  <link name="left_hip_pitch">
    <inertial>
      <origin rpy="0 0 0" xyz="0.060537 0.000521 -0.038857"/>
      <mass value="6.244279"/>
      <inertia ixx="0.011533" ixy="-0.000171" ixz="0.000148" iyy="0.033345" iyz="0.000178" izz="0.033958"/>
    </inertial>
    <visual>
      <origin rpy="0 0 0" xyz="0 0 0"/>
      <geometry>
        <mesh filename="stl/hip-pitch.stl"/>
      </geometry>
      <material name="scarlet">
        <color rgba="0.89 0.13 0.0 1"/>
      </material>
    </visual>
    <collision>
      <origin rpy="0 0 0" xyz="0 0 0"/>
      <geometry>
        <mesh filename="stl/hip-pitch.stl"/>
      </geometry>
    </collision>
  </link>
  <link name="left_knee">
    <inertial>
      <origin rpy="0 0 0" xyz="0.045641 0.042154 0.001657"/>
      <mass value="1.227077"/>
      <inertia ixx="0.002643" ixy="-0.001832" ixz="6.6e-05" iyy="0.005098" iyz="4.5e-05" izz="0.007019"/>
    </inertial>
    <visual>
      <origin rpy="0 0 0" xyz="0 0 0"/>
      <geometry>
        <mesh filename="stl/knee.stl"/>
      </geometry>
      <material name="grey">
        <color rgba="0.35 0.35 0.35 1"/>
      </material>
    </visual>
    <collision>
      <origin rpy="0 0 0" xyz="0 0 0"/>
      <geometry>
        <mesh filename="stl/knee.stl"/>
      </geometry>
    </collision>
  </link>
  <link name="left_shin">
    <inertial>
      <origin rpy="0 0 0" xyz="0.174265 0.010265 0.00107"/>
      <mass value="0.895793"/>
      <inertia ixx="0.001128" ixy="0.001098" ixz="0.000196" iyy="0.022492" iyz="-3e-06" izz="0.022793"/>
    </inertial>
    <visual>
      <origin rpy="0 0 0" xyz="0 0 0"/>
      <geometry>
        <mesh filename="stl/shin.stl"/>
      </geometry>
      <material name="scarlet">
        <color rgba="0.89 0.13 0.0 1"/>
      </material>
    </visual>
    <collision>
      <origin rpy="0 0 0" xyz="0 0 0"/>
      <geometry>
        <mesh filename="stl/shin.stl"/>
      </geometry>
    </collision>
  </link>
  
  <link name="left_shoulder_roll">
    <inertial>
      <origin rpy="0 0 0" xyz="9e-06 -0.003158 0.023405"/>
      <mass value="0.535396"/>
      <inertia ixx="0.000704" ixy="1.4e-05" ixz="1.2e-05" iyy="0.00075" iyz="3.5e-05" izz="0.000298"/>
    </inertial>
    <visual>
      <origin rpy="0 0 0" xyz="0 0 0"/>
      <geometry>
        <mesh filename="stl/arm-L1.stl"/>
      </geometry>
      <material name="grey">
        <color rgba="0.35 0.35 0.35 1"/>
      </material>
    </visual>
    <collision>
      <origin rpy="0 0 0" xyz="0 0 0"/>
      <geometry>
        <mesh filename="stl/arm-L1.stl"/>
      </geometry>
    </collision>
  </link>
  <link name="left_shoulder_pitch">
    <inertial>
      <origin rpy="0 0 0" xyz="-4.2e-05 -0.061882 -0.073788"/>
      <mass value="1.440357"/>
      <inertia ixx="0.006761" ixy="-6e-06" ixz="-3e-06" iyy="0.002087" iyz="-0.002046" izz="0.005778"/>
    </inertial>
    <visual>
      <origin rpy="0 0 0" xyz="0 0 0"/>
      <geometry>
        <mesh filename="stl/arm-L2.stl"/>
      </geometry>
      <material name="scarlet">
        <color rgba="0.89 0.13 0.0 1"/>
      </material>
    </visual>
    <collision>
      <origin rpy="0 0 0" xyz="0 0 0"/>
      <geometry>
        <mesh filename="stl/arm-L2.stl"/>
      </geometry>
    </collision>
  </link>
  <link name="left_shoulder_yaw">
    <inertial>
      <origin rpy="0 0 0" xyz="-3e-05 -0.001937 0.11407"/>
      <mass value="1.065387"/>
      <inertia ixx="0.006967" ixy="1e-06" ixz="-1e-06" iyy="0.007003" iyz="1.5e-05" izz="0.000673"/>
    </inertial>
    <visual>
      <origin rpy="0 0 0" xyz="0 0 0"/>
      <geometry>
        <mesh filename="stl/arm-L3.stl"/>
      </geometry>
      <material name="grey">
        <color rgba="0.35 0.35 0.35 1"/>
      </material>
    </visual>
    <collision>
      <origin rpy="0 0 0" xyz="0 0 0"/>
      <geometry>
        <mesh filename="stl/arm-L3.stl"/>
      </geometry>
    </collision>
  </link>
  <link name="left_elbow">
    <inertial>
      <origin rpy="0 0 0" xyz="0.107996 -0.000521 -0.017765"/>
      <mass value="0.550582"/>
      <inertia ixx="0.000476" ixy="2.9e-05" ixz="0.001403" iyy="0.009564" iyz="1.5e-05" izz="-9e-06"/>
    </inertial>
    <visual>
      <origin rpy="0 0 0" xyz="0 0 0"/>
      <geometry>
        <mesh filename="stl/arm-L4.stl"/>
      </geometry>
      <material name="light_grey">
        <color rgba="0.75 0.75 0.75 1"/>
      </material>
    </visual>
    <collision>
      <origin rpy="0 0 0" xyz="0 0 0"/>
      <geometry>
        <mesh filename="stl/arm-L4.stl"/>
      </geometry>
    </collision>
  </link>
  <link name="right_hip_roll">
    <inertial>
      <origin rpy="0 0 0" xyz="-0.001967 -0.000244 0.031435"/>
      <mass value="0.915088"/>
      <inertia ixx="0.001017" ixy="3e-06" ixz="1.3e-05" iyy="0.001148" iyz="4e-06" izz="0.000766"/>
    </inertial>
    <visual>
      <origin rpy="0 0 0" xyz="0 0 0"/>
      <geometry>
        <mesh filename="stl/hip-yaw-housing.stl" scale="1 -1 1"/>
      </geometry>
      <material name="grey">
        <color rgba="0.35 0.35 0.35 1"/>
      </material>
    </visual>
    <collision>
      <origin rpy="0 0 0" xyz="0 0 0"/>
      <geometry>
        <mesh filename="stl/hip-yaw-housing.stl" scale="1 -1 1"/>
      </geometry>
    </collision>
  </link>
  <link name="right_hip_yaw">
    <inertial>
      <origin rpy="0 0 0" xyz="1e-05 0.001945 0.042033"/>
      <mass value="0.818753"/>
      <inertia ixx="0.001627" ixy="1e-06" ixz="2e-06" iyy="0.001929" iyz="-5.3e-05" izz="0.00077"/>
    </inertial>
    <visual>
      <origin rpy="0 0 0" xyz="0 0 0"/>
      <geometry>
        <mesh filename="stl/hip-pitch-housing.stl" scale="1 -1 1"/>
      </geometry>
      <material name="light_grey">
        <color rgba="0.75 0.75 0.75 1"/>
      </material>
    </visual>
    <collision>
      <origin rpy="0 0 0" xyz="0 0 0"/>
      <geometry>
        <mesh filename="stl/hip-pitch-housing.stl" scale="1 -1 1"/>
      </geometry>
    </collision>
  </link>
  <link name="right_hip_pitch">
    <inertial>
      <origin rpy="0 0 0" xyz="0.060537 -0.000521 -0.038857"/>
      <mass value="6.244279"/>
      <inertia ixx="0.011533" ixy="0.000171" ixz="0.000148" iyy="0.033345" iyz="-0.000178" izz="0.033958"/>
    </inertial>
    <visual>
      <origin rpy="0 0 0" xyz="0 0 0"/>
      <geometry>
        <mesh filename="stl/hip-pitch.stl" scale="1 -1 1"/>
      </geometry>
      <material name="scarlet">
        <color rgba="0.89 0.13 0.0 1"/>
      </material>
    </visual>
    <collision>
      <origin rpy="0 0 0" xyz="0 0 0"/>
      <geometry>
        <mesh filename="stl/hip-pitch.stl" scale="1 -1 1"/>
      </geometry>
    </collision>
  </link>
  <link name="right_knee">
    <inertial>
      <origin rpy="0 0 0" xyz="0.045641 -0.042154 0.001657"/>
      <mass value="1.227077"/>
      <inertia ixx="0.002643" ixy="0.001832" ixz="6.6e-05" iyy="0.005098" iyz="-4.5e-05" izz="0.007019"/>
    </inertial>
    <visual>
      <origin rpy="0 0 0" xyz="0 0 0"/>
      <geometry>
        <mesh filename="stl/knee.stl" scale="1 -1 1"/>
      </geometry>
      <material name="grey">
        <color rgba="0.35 0.35 0.35 1"/>
      </material>
    </visual>
    <collision>
      <origin rpy="0 0 0" xyz="0 0 0"/>
      <geometry>
        <mesh filename="stl/knee.stl" scale="1 -1 1"/>
      </geometry>
    </collision>
  </link>
  <link name="right_shin">
    <inertial>
      <origin rpy="0 0 0" xyz="0.174265 -0.010265 0.00107"/>
      <mass value="0.895793"/>
      <inertia ixx="0.001128" ixy="-0.001098" ixz="0.000196" iyy="0.022492" iyz="3e-06" izz="0.022793"/>
    </inertial>
    <visual>
      <origin rpy="0 0 0" xyz="0 0 0"/>
      <geometry>
        <mesh filename="stl/shin.stl" scale="1 -1 1"/>
      </geometry>
      <material name="scarlet">
        <color rgba="0.89 0.13 0.0 1"/>
      </material>
    </visual>
    <collision>
      <origin rpy="0 0 0" xyz="0 0 0"/>
      <geometry>
        <mesh filename="stl/shin.stl" scale="1 -1 1"/>
      </geometry>
    </collision>
  </link>
  








































  <!-- ATTACH HOVERBOARD HERE -->

  <link name="bar">
    <inertial>
      <origin rpy="0 0 0" xyz="0 0 0"/>
      <mass value="15.028392"/>
      <inertia ixx="0.0045" ixy="0" ixz="0" iyy="0.005" iyz="0" izz="0.0045" />
    </inertial>
    <visual>
      <origin rpy="1.57 0 1.57" xyz="0 0 0"/>
      <geometry>
        <!-- <mesh filename="meshes/base.obj" scale="0.04 0.03 0.03"/> -->
        <box size="0.05 0.05 0.7"/>
      </geometry>
      <material name="grey">
        <color rgba="0.89 0.13 0.0 1"/>
      </material>
    </visual>
    <collision>
      <origin rpy="1.57  0 1.57 " xyz="0 0 0"/>
      <geometry>
        <!-- <mesh filename="meshes/base.obj" scale="0.04 0.03 0.03"/> -->
        <box size="0.05 0.05 0.5"/>
      </geometry>
    </collision>
</link>

<joint name="bar_to_torso" type="fixed">
  <origin rpy="0 1.57 0" xyz=" 0 0 -0.35"/>
      <!-- <axis xyz="1 1 1"/> -->
    <parent link="torso"/>
    <child link="bar"/>
</joint>


<link name="base">
    <inertial>
      <origin rpy="0 0 0" xyz="0 0 0"/>
      <mass value="15.028392"/>
      <inertia ixx="0.0045" ixy="0" ixz="0" iyy="0.005" iyz="0" izz="0.0045" />
    </inertial>
    <visual>
      <origin rpy="1.57 0 1.57" xyz="0 0 0"/>
      <geometry>
        <mesh filename="meshes/base.obj" scale="0.04 0.03 0.03"/>
        <!-- <box size="0.2 1.0 0.3"/> -->
      </geometry>
      <material name="scarlet">
        <color rgba="0.89 0.13 0.0 1"/>
      </material>
    </visual>
    <collision>
      <origin rpy="1.57  0 1.57 " xyz="0 0 0"/>
      <geometry>
        <mesh filename="meshes/base.obj" scale="0.04 0.03 0.03"/>
        <!-- <box size="0.2 1.0 0.3"/> -->
      </geometry>
    </collision>
</link>

<!-- <joint name="base_to_digit_left" type="fixed">
  <origin rpy="2 0 -0.7" xyz="0.4 0.1 -0.08"/>
    <parent link="left_shin"/>
    <child link="base"/>
</joint>
 -->
<joint name="base_to_bar" type="fixed">
  <origin rpy="0 -1.57 0" xyz="0.4 -0.4 0"/>
      <axis xyz="1 1 1"/>
    <parent link="bar"/>
    <child link="base"/>
</joint>


<link name="right_wheel">
    <inertial>
      <origin rpy="1.57 0 1.57" xyz="0 0 0"/>
      <mass value="4.028392"/>
      <inertia ixx="0.0045" ixy="0" ixz="0" iyy="0.005" iyz="0" izz="0.0045" />
    </inertial>
    <visual>
      <origin rpy="1.57 0 1.57" xyz="0 0 0"/>
      <geometry>
        <mesh filename="meshes/wheel.stl" scale="0.03 0.03 0.03"/>
         <!-- <cylinder radius="0.2" length="0.1"/> -->
      </geometry>
      <material name="black">
        <color rgba="0.2 0.2 0.2 1"/>
      </material>
    </visual>
    <collision>
      <origin rpy="1.57  0 1.57 " xyz="0 0 0"/>
      <geometry>
        <mesh filename="meshes/wheel.stl" scale="0.03 0.03 0.03"/>
        <!-- <cylinder radius="0.2" length="0.1"/> -->
      </geometry>
    </collision>
</link>

<joint name="wheelr_to_base" type="continuous">
  <origin rpy="0 0 3.14159265359" xyz="0 0 0"/>
    <axis xyz="0 1 0"/>
    <parent link="base"/>
    <child link="right_wheel"/>
    <limit effort="8.85" velocity="34.8" />
</joint>

<link name="left_wheel">
    <inertial>
      <origin rpy="1.57 0 1.57" xyz="0 0 0"/>
      <mass value="4.028392"/>
      <inertia ixx="0.0045" ixy="0" ixz="0" iyy="0.005" iyz="0" izz="0.0045" />
    </inertial>
    <visual>
      <origin rpy="1.57 0 1.57" xyz="0 0 0"/>
      <geometry>
        <mesh filename="meshes/wheel.stl" scale="0.03 0.03 0.03"/>
         <!-- <cylinder radius="0.2" length="0.1"/> -->
      </geometry>
      <material name="black">
        <color rgba="0.2 0.2 0.2 1"/>
      </material>
    </visual>
    <collision>
      <origin rpy="1.57  0 1.57 " xyz="0 0 0"/>
      <geometry>
        <mesh filename="meshes/wheel.stl" scale="0.03 0.03 0.03"/>
        <!-- <cylinder radius="0.2" length="0.1"/> -->
      </geometry>
    </collision>
</link>

<joint name="wheell_to_base" type="continuous">
  <origin rpy="0 0 0" xyz="0 0.8 0"/>
    <axis xyz="0 1 0"/>
    <parent link="base"/>
    <child link="left_wheel"/>
    <limit effort="8.85" velocity="34.8" />
</joint>
<!-- 
<link name="balance">
    <inertial>
      <origin rpy="0 0 0" xyz="0 0 0"/>
      <mass value="14.028392"/>
      <inertia ixx="0.0045" ixy="0" ixz="0" iyy="0.005" iyz="0" izz="0.0045" />
    </inertial>
    <visual>
      <origin rpy="0 0 0" xyz="0 0 0"/>
      <geometry>
        <box size="0.5 0.05 0.05"/>
      </geometry>
      <material name="scarlet">
      </material>
    </visual>
    <collision>
      <origin rpy="0 0 0 " xyz="0 0 0"/>
      <geometry>
        <box size="0.5 0.05 0.05"/>
      </geometry>
    </collision>
</link>

<joint name="balance_to_base" type="fixed">
  <origin rpy="0 0 0" xyz="-0.25 0.5 0"/>
    <parent link="base"/>
    <child link="balance"/>
</joint>

<link name="third_wheel">
    <inertial>
      <origin rpy="0 0 0" xyz="0 0 0"/>
      <mass value="4.028392"/>
      <inertia ixx="0.0045" ixy="0" ixz="0" iyy="0.005" iyz="0" izz="0.0045" />
    </inertial>
    <visual>
      <origin rpy="0 0 0" xyz="0 0 0"/>
      <geometry>
         <sphere radius="0.15"/>
      </geometry>
      <material name="black">
        <color rgba="0.2 0.2 0.2 1"/>
      </material>
    </visual>
    <collision>
      <origin rpy="0 0 0" xyz="0 0 0"/>
      <geometry>
        <sphere radius="0.15"/>
      </geometry>
    </collision>
</link>

<joint name="twheel_to_balance" type="fixed">
  <origin rpy="0 0 0" xyz="-0.25 0.0 0"/>
    <axis xyz="0 1 0"/>
    <parent link="balance"/>
    <child link="third_wheel"/>
</joint> -->




















































  
  <link name="right_shoulder_roll">
    <inertial>
      <origin rpy="0 0 0" xyz="9e-06 0.003158 0.023405"/>
      <mass value="0.535396"/>
      <inertia ixx="0.000704" ixy="-1.4e-05" ixz="1.2e-05" iyy="0.00075" iyz="-3.5e-05" izz="0.000298"/>
    </inertial>
    <visual>
      <origin rpy="0 0 0" xyz="0 0 0"/>
      <geometry>
        <mesh filename="stl/arm-L1.stl" scale="1 -1 1"/>
      </geometry>
      <material name="grey">
        <color rgba="0.35 0.35 0.35 1"/>
      </material>
    </visual>
    <collision>
      <origin rpy="0 0 0" xyz="0 0 0"/>
      <geometry>
        <mesh filename="stl/arm-L1.stl" scale="1 -1 1"/>
      </geometry>
    </collision>
  </link>
  <link name="right_shoulder_pitch">
    <inertial>
      <origin rpy="0 0 0" xyz="-4.2e-05 0.061882 -0.073788"/>
      <mass value="1.440357"/>
      <inertia ixx="0.006761" ixy="6e-06" ixz="-3e-06" iyy="0.002087" iyz="0.002046" izz="0.005778"/>
    </inertial>
    <visual>
      <origin rpy="0 0 0" xyz="0 0 0"/>
      <geometry>
        <mesh filename="stl/arm-L2.stl" scale="1 -1 1"/>
      </geometry>
      <material name="scarlet">
        <color rgba="0.89 0.13 0.0 1"/>
      </material>
    </visual>
    <collision>
      <origin rpy="0 0 0" xyz="0 0 0"/>
      <geometry>
        <mesh filename="stl/arm-L2.stl" scale="1 -1 1"/>
      </geometry>
    </collision>
  </link>
  <link name="right_shoulder_yaw">
    <inertial>
      <origin rpy="0 0 0" xyz="-3e-05 0.001937 0.11407"/>
      <mass value="1.065387"/>
      <inertia ixx="0.006967" ixy="-1e-06" ixz="-1e-06" iyy="0.007003" iyz="-1.5e-05" izz="0.000673"/>
    </inertial>
    <visual>
      <origin rpy="0 0 0" xyz="0 0 0"/>
      <geometry>
        <mesh filename="stl/arm-L3.stl" scale="1 -1 1"/>
      </geometry>
      <material name="grey">
        <color rgba="0.35 0.35 0.35 1"/>
      </material>
    </visual>
    <collision>
      <origin rpy="0 0 0" xyz="0 0 0"/>
      <geometry>
        <mesh filename="stl/arm-L3.stl" scale="1 -1 1"/>
      </geometry>
    </collision>
  </link>
  <link name="right_elbow">
    <inertial>
      <origin rpy="0 0 0" xyz="0.107996 0.000521 -0.017765"/>
      <mass value="0.550582"/>
      <inertia ixx="0.000476" ixy="-2.9e-05" ixz="0.001403" iyy="0.009564" iyz="-1.5e-05" izz="-9e-06"/>
    </inertial>
    <visual>
      <origin rpy="0 0 0" xyz="0 0 0"/>
      <geometry>
        <mesh filename="stl/arm-L4.stl" scale="1 -1 1"/>
      </geometry>
      <material name="light_grey">
        <color rgba="0.75 0.75 0.75 1"/>
      </material>
    </visual>
    <collision>
      <origin rpy="0 0 0" xyz="0 0 0"/>
      <geometry>
        <mesh filename="stl/arm-L4.stl" scale="1 -1 1"/>
      </geometry>
    </collision>
  </link>





  <!-- MY STUFF -->
  <!-- right gripper -->
  <link name="right_wrist">
    <inertial>
      <origin rpy="0 0 0" xyz="0.107996 0.000521 -0.017765"/>
      <mass value="0.550582"/>
      <inertia ixx="0.000476" ixy="-2.9e-05" ixz="0.001403" iyy="0.009564" iyz="-1.5e-05" izz="-9e-06"/>
    </inertial>
    <visual>
      <origin rpy="0 1.5707 1.5707 " xyz="0 0 0"/>
      <geometry>
        <cylinder radius="0.025" length="0.05"/>
      </geometry>
      <material name="blue">
        <color rgba="0.05 0.05 0.75 0.9"/>
      </material>
    </visual>
    <collision>
      <origin rpy="0 1.5707 1.5707" xyz="0 0 0"/>
      <geometry>
        <cylinder radius="0.025" length="0.05"/>
      </geometry>
    </collision>
  </link>
  <joint name="right_wrist_joint" type="revolute">
    <origin rpy="-1.57079632679 0.1926991 0" xyz="0.38 -0.0 -0.06"/>
    <parent link="right_elbow"/>
    <child link="right_wrist"/>
    <axis xyz="0 1 0"/>
    <limit effort="0" lower="-1.57" upper="1.57" velocity="10"/>
  </joint>

  <link name="gripper_r_base">
    <inertial>
      <origin rpy="0 0 0" xyz="0 0 0"/>
      <mass value="0.2"/>
      <inertia ixx="0.0001" ixy="0" ixz="0" iyy="0.0001" iyz="0" izz="0.0001"/>
    </inertial>
    <visual>
      <origin rpy="0 1.5707 0" xyz="0 0 0"/>
      <geometry>
        <mesh filename="/home/bill/garage/kfp_v2/morpheus/models/yumi_description/meshes/gripper/base.stl"/>
      </geometry>
      <material name="Light_Grey"/>
    </visual>
    <collision>
      <origin rpy="0 1.5707 0" xyz="0 0 0"/>
      <geometry>
        <mesh filename="/home/bill/garage/kfp_v2/morpheus/models/yumi_description/meshes/gripper/coarse/base.stl"/>
      </geometry>
      <material name="Light_Grey"/>
    </collision>
  </link>

  <joint name="gripper_right_wrist_joint" type="revolute">
    <origin rpy="0 0 0" xyz="0 0 0"/>
    <parent link="right_wrist"/>
    <child link="gripper_r_base"/>
    <axis xyz="1 0 0"/>
    <limit effort="0" lower="-1.57" upper="1.57" velocity="10"/>
  </joint>

  <joint name="gripper_r_joint" type="prismatic">
    <parent link="gripper_r_base"/>
    <child link="gripper_r_finger_r"/>
    <origin rpy="0 1.57 0" xyz="0.09 -0.0065 0.0"/>
    <axis xyz="-1 0 0"/>
    <limit effort="300" lower="0" upper="0.025" velocity="0.02"/>
    <dynamics damping="0.5"/>
  </joint>
  <link name="gripper_r_finger_r">
    <inertial>
      <origin rpy="0 0 0" xyz="0 0 0"/>
      <mass value="0.01"/>
      <inertia ixx="0.000001" ixy="0" ixz="0" iyy="0.000001" iyz="0" izz="0.000001"/>
    </inertial>
    <visual>
      <origin rpy="0 0 0" xyz="0 0 0"/>
      <geometry>
        <mesh filename="/home/bill/garage/kfp_v2/morpheus/models/yumi_description/meshes/gripper/finger.stl"/>
      </geometry>
      <material name="scarlet"/>
    </visual>
    <collision>
      <origin rpy="0 0 0" xyz="0 0 0"/>
      <geometry>
        <mesh filename="/home/bill/garage/kfp_v2/morpheus/models/yumi_description/meshes/gripper/coarse/finger.stl"/>
      </geometry>
      <material name="Grey"/>
    </collision>
  </link>

  <joint name="gripper_r_joint_m" type="prismatic">
      <parent link="gripper_r_base"/>
      <child link="gripper_r_finger_l"/>
      <origin rpy="0 -1.57 3.14159265359" xyz="0.09 0.0065 0.0"/>
      <axis xyz="-1 0 0"/>
      <limit effort="300" lower="0" upper="0.025" velocity="0.02"/>
      <dynamics damping="0.5"/>
      <mimic joint="gripper_r_joint"/>
    </joint>
    <link name="gripper_r_finger_l">
      <inertial>
        <origin rpy="0 0 0" xyz="0 0 0"/>
        <mass value="0.01"/>
        <inertia ixx="0.000001" ixy="0" ixz="0" iyy="0.000001" iyz="0" izz="0.000001"/>
      </inertial>
      <visual>
        <origin rpy="0 0 0" xyz="0 0 0"/>
        <geometry>
          <mesh filename="/home/bill/garage/kfp_v2/morpheus/models/yumi_description/meshes/gripper/finger.stl"/>
        </geometry>
        <material name="grey"/>
      </visual>
      <collision>
        <origin rpy="0 0 0" xyz="0 0 0"/>
        <geometry>
          <mesh filename="/home/bill/garage/kfp_v2/morpheus/models/yumi_description/meshes/gripper/coarse/finger.stl"/>
        </geometry>
        <material name="Grey"/>
      </collision>
    </link>

    <!-- left gripper -->
    <link name="left_wrist">
    <inertial>
      <origin rpy="0 0 0" xyz="0.107996 0.000521 -0.017765"/>
      <mass value="0.550582"/>
      <inertia ixx="0.000476" ixy="-2.9e-05" ixz="0.001403" iyy="0.009564" iyz="-1.5e-05" izz="-9e-06"/>
    </inertial>
    <visual>
      <origin rpy="0 1.5707 1.5707 " xyz="0 0 0"/>
      <geometry>
        <cylinder radius="0.025" length="0.05"/>
      </geometry>
      <material name="blue">
        <color rgba="0.05 0.05 0.75 0.9"/>
      </material>
    </visual>
    <collision>
      <origin rpy="0 1.5707 1.5707" xyz="0 0 0"/>
      <geometry>
        <cylinder radius="0.025" length="0.05"/>
      </geometry>
    </collision>
  </link>
  <joint name="left_wrist_joint" type="revolute">
    <origin rpy="-1.57079632679 0.1926991 0" xyz="0.38 -0.0 -0.06"/>
    <parent link="left_elbow"/>
    <child link="left_wrist"/>
    <axis xyz="0 1 0"/>
    <limit effort="0" lower="-1.57" upper="1.57" velocity="10"/>
  </joint>

  <link name="gripper_l_base">
    <inertial>
      <origin rpy="0 0 0" xyz="0 0 0"/>
      <mass value="0.2"/>
      <inertia ixx="0.0001" ixy="0" ixz="0" iyy="0.0001" iyz="0" izz="0.0001"/>
    </inertial>
    <visual>
      <origin rpy="0 1.5707 0" xyz="0 0 0"/>
      <geometry>
        <mesh filename="/home/bill/garage/kfp_v2/morpheus/models/yumi_description/meshes/gripper/base.stl"/>
      </geometry>
      <material name="Light_Grey"/>
    </visual>
    <collision>
      <origin rpy="0 1.5707 0" xyz="0 0 0"/>
      <geometry>
        <mesh filename="/home/bill/garage/kfp_v2/morpheus/models/yumi_description/meshes/gripper/coarse/base.stl"/>
      </geometry>
      <material name="Light_Grey"/>
    </collision>
  </link>

  <joint name="gripper_left_wrist_joint" type="revolute">
    <origin rpy="0 0 0" xyz="0 0 0"/>
    <parent link="left_wrist"/>
    <child link="gripper_l_base"/>
    <axis xyz="1 0 0"/>
    <limit effort="0" lower="-1.57" upper="1.57" velocity="10"/>
  </joint>

  <joint name="gripper_l_joint" type="prismatic">
    <parent link="gripper_l_base"/>
    <child link="gripper_l_finger_r"/>
    <origin rpy="0 1.57 0" xyz="0.09 -0.0065 0.0"/>
    <axis xyz="-1 0 0"/>
    <limit effort="300" lower="0" upper="0.025" velocity="0.02"/>
    <dynamics damping="0.5"/>
  </joint>
  <link name="gripper_l_finger_r">
    <inertial>
      <origin rpy="0 0 0" xyz="0 0 0"/>
      <mass value="0.01"/>
      <inertia ixx="0.000001" ixy="0" ixz="0" iyy="0.000001" iyz="0" izz="0.000001"/>
    </inertial>
    <visual>
      <origin rpy="0 0 0" xyz="0 0 0"/>
      <geometry>
        <mesh filename="/home/bill/garage/kfp_v2/morpheus/models/yumi_description/meshes/gripper/finger.stl"/>
      </geometry>
      <material name="scarlet"/>
    </visual>
    <collision>
      <origin rpy="0 0 0" xyz="0 0 0"/>
      <geometry>
        <mesh filename="/home/bill/garage/kfp_v2/morpheus/models/yumi_description/meshes/gripper/coarse/finger.stl"/>
      </geometry>
      <material name="Grey"/>
    </collision>
  </link>

  <joint name="gripper_l_joint_m" type="prismatic">
      <parent link="gripper_l_base"/>
      <child link="gripper_l_finger_l"/>
      <origin rpy="0 -1.57 3.14159265359" xyz="0.09 0.0065 0.0"/>
      <axis xyz="-1 0 0"/>
      <limit effort="300" lower="0" upper="0.025" velocity="0.02"/>
      <dynamics damping="0.5"/>
      <mimic joint="gripper_l_joint"/>
    </joint>
    <link name="gripper_l_finger_l">
      <inertial>
        <origin rpy="0 0 0" xyz="0 0 0"/>
        <mass value="0.01"/>
        <inertia ixx="0.000001" ixy="0" ixz="0" iyy="0.000001" iyz="0" izz="0.000001"/>
      </inertial>
      <visual>
        <origin rpy="0 0 0" xyz="0 0 0"/>
        <geometry>
          <mesh filename="/home/bill/garage/kfp_v2/morpheus/models/yumi_description/meshes/gripper/finger.stl"/>
        </geometry>
        <material name="grey"/>
      </visual>
      <collision>
        <origin rpy="0 0 0" xyz="0 0 0"/>
        <geometry>
          <mesh filename="/home/bill/garage/kfp_v2/morpheus/models/yumi_description/meshes/gripper/coarse/finger.stl"/>
        </geometry>
        <material name="Grey"/>
      </collision>
    </link>
  















  <joint name="hip_abduction_left" type="continuous">
    <origin rpy="1.57079632679 -1.1955506 -1.57079632679" xyz="-0.001 0.091 0"/>
    <axis xyz="0 0 1"/>
    <parent link="torso"/>
    <child link="left_hip_roll"/>
    <limit effort="1.4" lower="-1.0472" upper="1.0472" velocity="12.15"/>
  </joint>
  <joint name="hip_rotation_left" type="continuous">
    <origin rpy="0 -1.57079632679 0" xyz="-0.0505 0 0.044"/>
    <axis xyz="0 0 1"/>
    <parent link="left_hip_roll"/>
    <child link="left_hip_yaw"/>
    <limit effort="1.4" lower="-0.698132" upper="0.698132" velocity="12.15"/>
  </joint>
  <joint name="hip_flexion_left" type="continuous">
    <origin rpy="-1.57079632679 -0.785398163397 3.14159265359" xyz="0 0.004 0.068"/>
    <axis xyz="0 0 -1"/>
    <parent link="left_hip_yaw"/>
    <child link="left_hip_pitch"/>
    <limit effort="12.5" lower="-1.0472" upper="1.57079632679" velocity="8.5"/>
  </joint>
  <joint name="knee_joint_left" type="continuous">
    <origin rpy="0 0 -1.57079632679" xyz="0.12 0 0.0045"/>
    <axis xyz="0 0 1"/>
    <parent link="left_hip_pitch"/>
    <child link="left_knee"/>
    <limit effort="12.5" lower="-1.2392" upper="0.8727" velocity="8.5085"/>
  </joint>
  <joint name="knee_to_shin_left" type="continuous">
    <origin rpy="0 0 0" xyz="0.060677 0.047406 0"/>
    <axis xyz="0 0 1"/>
    <parent link="left_knee"/>
    <child link="left_shin"/>
    <limit effort="0" lower="-0.35" upper="0.35" velocity="10"/>
  </joint>
 

  <joint name="shoulder_roll_joint_left" type="continuous">
    <origin rpy="-1.57079632679 -1.3962633 1.57079632679" xyz="-0.001 0.12 0.4"/>
    <axis xyz="0 0 1"/>
    <parent link="torso"/>
    <child link="left_shoulder_roll"/>
    <limit effort="1.4" lower="-1.309" upper="1.309" velocity="12.5"/>
  </joint>
  <joint name="shoulder_pitch_joint_left" type="continuous">
    <origin rpy="1.57079632679 0.785398163397 -0.2792527" xyz="-0.00317 -0.011055 0.0555"/>
    <axis xyz="0 0 -1"/>
    <parent link="left_shoulder_roll"/>
    <child link="left_shoulder_pitch"/>
    <limit effort="1.4" lower="-2.5307" upper="2.5307" velocity="12.5"/>
  </joint>
  <joint name="shoulder_yaw_joint_left" type="continuous">
    <origin rpy="1.57079632679 0 0" xyz="0 -0.165 -0.1"/>
    <axis xyz="0 0 1"/>
    <parent link="left_shoulder_pitch"/>
    <child link="left_shoulder_yaw"/>
    <limit effort="1.4" lower="-1.7453" upper="1.7453" velocity="10"/>
  </joint>
  <joint name="elbow_joint_left" type="continuous">
    <origin rpy="1.57079632679 -0.3926991 0" xyz="0 -0.0385 0.185"/>
    <axis xyz="0 0 1"/>
    <parent link="left_shoulder_yaw"/>
    <child link="left_elbow"/>
    <limit effort="1.4" lower="-1.3526" upper="1.3526" velocity="12.5"/>
  </joint>
  <joint name="hip_abduction_right" type="continuous">
    <origin rpy="-1.57079632679 -1.1955506 1.57079632679" xyz="-0.001 -0.091 0"/>
    <axis xyz="0 0 1"/>
    <parent link="torso"/>
    <child link="right_hip_roll"/>
    <limit effort="1.4" lower="-1.0472" upper="1.0472" velocity="12.15"/>
  </joint>
  <joint name="hip_rotation_right" type="continuous">
    <origin rpy="0 -1.57079632679 0" xyz="-0.0505 0 0.044"/>
    <axis xyz="0 0 1"/>
    <parent link="right_hip_roll"/>
    <child link="right_hip_yaw"/>
    <limit effort="1.4" lower="-0.698132" upper="0.698132" velocity="12.15"/>
  </joint>
  <joint name="hip_flexion_right" type="continuous">
    <origin rpy="1.57079632679 -0.785398163397 -3.14159265359" xyz="0 -0.004 0.068"/>
    <axis xyz="0 0 -1"/>
    <parent link="right_hip_yaw"/>
    <child link="right_hip_pitch"/>
    <limit effort="12.5" lower="-1.57079632679" upper="1.0472" velocity="8.5"/>
  </joint>
  <joint name="knee_joint_right" type="continuous">
    <origin rpy="0 0 1.57079632679" xyz="0.12 0 0.0045"/>
    <axis xyz="0 0 1"/>
    <parent link="right_hip_pitch"/>
    <child link="right_knee"/>
    <limit effort="12.5" lower="-0.8727" upper="1.2392" velocity="8.5085"/>
  </joint>
  <joint name="knee_to_shin_right" type="continuous">
    <origin rpy="0 0 0" xyz="0.060677 -0.047406 0"/>
    <axis xyz="0 0 1"/>
    <parent link="right_knee"/>
    <child link="right_shin"/>
    <limit effort="0" lower="-0.35" upper="0.35" velocity="10"/>
  </joint>
  

  <joint name="shoulder_roll_joint_right" type="continuous">
    <origin rpy="1.57079632679 -1.3962633 -1.57079632679" xyz="-0.001 -0.12 0.4"/>
    <axis xyz="0 0 1"/>
    <parent link="torso"/>
    <child link="right_shoulder_roll"/>
    <limit effort="1.4" lower="-1.309" upper="1.309" velocity="12.5"/>
  </joint>
  <joint name="shoulder_pitch_joint_right" type="continuous">
    <origin rpy="-1.57079632679 0.785398163397 0.2792527" xyz="-0.00317 0.011055 0.0555"/>
    <axis xyz="0 0 -1"/>
    <parent link="right_shoulder_roll"/>
    <child link="right_shoulder_pitch"/>
    <limit effort="1.4" lower="-2.5307" upper="2.5307" velocity="12.5"/>
  </joint>
  <joint name="shoulder_yaw_joint_right" type="continuous">
    <origin rpy="-1.57079632679 0 0" xyz="0 0.165 -0.1"/>
    <axis xyz="0 0 1"/>
    <parent link="right_shoulder_pitch"/>
    <child link="right_shoulder_yaw"/>
    <limit effort="1.4" lower="-1.7453" upper="1.7453" velocity="10"/>
  </joint>
  <joint name="elbow_joint_right" type="continuous">
    <origin rpy="-1.57079632679 -0.3926991 0" xyz="0 0.0385 0.185"/>
    <axis xyz="0 0 1"/>
    <parent link="right_shoulder_yaw"/>
    <child link="right_elbow"/>
    <limit effort="1.4" lower="-1.3526" upper="1.3526" velocity="12.5"/>
  </joint>
 
</robot>
